2025-09-19 10:01:40,380 [INFO] novinhub - Background workflow task scheduled.
2025-09-19 10:01:41,717 [INFO] novinhub - Background workflow task scheduled.
2025-09-19 10:03:52,987 [INFO] novinhub - Background workflow task scheduled successfully.
2025-09-19 10:03:52,993 [INFO] novinhub - Background task started. Running the async workflow.
2025-09-19 10:03:52,995 [INFO] novinhub - Running robot before checking email...
2025-09-19 10:03:53,010 [INFO] novinhub - Starting Selenium robot...
2025-09-19 10:04:17,401 [INFO] novinhub - Opened start URL.
2025-09-19 10:04:19,569 [INFO] novinhub - Login attempted.
2025-09-19 10:04:19,569 [INFO] novinhub - Selenium robot finished (skeleton).
2025-09-19 10:04:21,658 [INFO] novinhub - Authenticating Gmail API...
2025-09-19 10:04:22,430 [INFO] novinhub - Gmail service ready.
2025-09-19 10:04:22,431 [INFO] novinhub - Polling for report email for up to 180 seconds...
2025-09-19 10:04:23,588 [INFO] novinhub - No matching messages found for query.
2025-09-19 10:04:34,029 [INFO] novinhub - No matching messages found for query.
2025-09-19 10:04:44,458 [INFO] novinhub - No matching messages found for query.
2025-09-19 10:04:54,909 [INFO] novinhub - No matching messages found for query.
2025-09-19 10:05:05,342 [INFO] novinhub - No matching messages found for query.
2025-09-19 10:05:15,779 [INFO] novinhub - No matching messages found for query.
2025-09-19 10:05:26,530 [INFO] novinhub - No matching messages found for query.
2025-09-19 10:05:36,954 [INFO] novinhub - No matching messages found for query.
2025-09-19 10:05:47,375 [INFO] novinhub - No matching messages found for query.
2025-09-19 10:05:57,798 [INFO] novinhub - No matching messages found for query.
2025-09-19 10:06:08,287 [INFO] novinhub - No matching messages found for query.
2025-09-19 10:06:18,730 [INFO] novinhub - No matching messages found for query.
2025-09-19 10:06:29,160 [INFO] novinhub - No matching messages found for query.
2025-09-19 10:06:39,596 [INFO] novinhub - No matching messages found for query.
2025-09-19 10:06:50,027 [INFO] novinhub - No matching messages found for query.
2025-09-19 10:07:00,459 [INFO] novinhub - No matching messages found for query.
2025-09-19 10:07:10,882 [INFO] novinhub - No matching messages found for query.
2025-09-19 10:07:21,338 [INFO] novinhub - No matching messages found for query.
2025-09-19 10:07:31,769 [INFO] novinhub - No matching messages found for query.
2025-09-19 10:07:31,770 [WARNING] novinhub - Timeout while waiting for report email.
2025-09-19 10:07:31,772 [INFO] novinhub - Async workflow finished successfully in background.
2025-09-19 10:11:15,652 [INFO] novinhub - Background workflow task scheduled successfully.
2025-09-19 10:11:15,658 [INFO] novinhub - Background task started. Running the async workflow.
2025-09-19 10:11:15,659 [INFO] novinhub - Running robot before checking email...
2025-09-19 10:11:15,661 [INFO] novinhub - Starting Selenium robot...
2025-09-19 10:11:24,305 [INFO] novinhub - Opened start URL: https://app.novinhub.com/login?redirect=%2Fdashboard
2025-09-19 10:11:24,306 [INFO] novinhub - Attempting to log in...
2025-09-19 10:11:26,472 [INFO] novinhub - Login form submitted.
2025-09-19 10:11:29,015 [INFO] novinhub - Login successful, dashboard loaded.
2025-09-19 10:11:29,015 [INFO] novinhub - Navigating to automation page...
2025-09-19 10:11:29,088 [INFO] novinhub - Navigating to export numbers tab...
2025-09-19 10:11:30,167 [ERROR] novinhub - An error occurred during Selenium robot execution: Message: element click intercepted: Element <a class="text-gray-600 hover:bg-gray-50 hover:text-gray-900 hover:dark:bg-gray-700 group flex items-center rounded-md px-3 py-2 font-semibold" aria-current="page" href="/automation/166262/leed">...</a> is not clickable at point (1693, 450). Other element would receive the click: <div tabindex="-1" id=":re:" role="tooltip" class="z-40 min-w-[150px] whitespace-pre-wrap rounded-md bg-gray-500 px-4 py-2 text-center text-white dark:text-zinc-100" style="position: absolute; left: 0px; top: 0px; max-width: calc(-40px + 100vw); transform: translate(1674px, 426px); transition-property: opacity; transition-duration: 100ms;">...</div>
  (Session info: chrome=140.0.7339.128); For documentation on this error, please visit: https://www.selenium.dev/documentation/webdriver/troubleshooting/errors#elementclickinterceptedexception
Stacktrace:
	GetHandleVerifier [0x0xee0c13+66051]
	GetHandleVerifier [0x0xee0c54+66116]
	(No symbol) [0x0xcbdb33]
	(No symbol) [0x0xd0dd90]
	(No symbol) [0x0xd0c0f3]
	(No symbol) [0x0xd09ba7]
	(No symbol) [0x0xd08e2d]
	(No symbol) [0x0xcfd335]
	(No symbol) [0x0xd29f8c]
	(No symbol) [0x0xcfcd94]
	(No symbol) [0x0xd2a144]
	(No symbol) [0x0xd4b7f1]
	(No symbol) [0x0xd29d86]
	(No symbol) [0x0xcfb53e]
	(No symbol) [0x0xcfc414]
	GetHandleVerifier [0x0x1128a13+2457603]
	GetHandleVerifier [0x0x11239d2+2437058]
	GetHandleVerifier [0x0xf097f2+232930]
	GetHandleVerifier [0x0xef9a18+167944]
	GetHandleVerifier [0x0xf0092d+196381]
	GetHandleVerifier [0x0xee8ee8+99544]
	GetHandleVerifier [0x0xee9082+99954]
	GetHandleVerifier [0x0xed322a+10266]
	BaseThreadInitThunk [0x0x76395d49+25]
	RtlInitializeExceptionChain [0x0x775ad6db+107]
	RtlGetAppContainerNamedObjectPath [0x0x775ad661+561]
Traceback (most recent call last):
  File "D:\MyProject\SalamatSaleDepartment\MainWebSite\WWW\python\ImportPhone_Novinhub.py", line 349, in run_robot
    wait.until(EC.presence_of_element_located((By.CSS_SELECTOR, export_tab_selector))).click()
    ~~~~~~~~~~~~~~~~~~~~~~~~~~~~~~~~~~~~~~~~~~~~~~~~~~~~~~~~~~~~~~~~~~~~~~~~~~~~~~~~~~~~~~~~^^
  File "C:\Users\amira\AppData\Local\Programs\Python\Python313\Lib\site-packages\selenium\webdriver\remote\webelement.py", line 120, in click
    self._execute(Command.CLICK_ELEMENT)
    ~~~~~~~~~~~~~^^^^^^^^^^^^^^^^^^^^^^^
  File "C:\Users\amira\AppData\Local\Programs\Python\Python313\Lib\site-packages\selenium\webdriver\remote\webelement.py", line 573, in _execute
    return self._parent.execute(command, params)
           ~~~~~~~~~~~~~~~~~~~~^^^^^^^^^^^^^^^^^
  File "C:\Users\amira\AppData\Local\Programs\Python\Python313\Lib\site-packages\selenium\webdriver\remote\webdriver.py", line 458, in execute
    self.error_handler.check_response(response)
    ~~~~~~~~~~~~~~~~~~~~~~~~~~~~~~~~~^^^^^^^^^^
  File "C:\Users\amira\AppData\Local\Programs\Python\Python313\Lib\site-packages\selenium\webdriver\remote\errorhandler.py", line 232, in check_response
    raise exception_class(message, screen, stacktrace)
selenium.common.exceptions.ElementClickInterceptedException: Message: element click intercepted: Element <a class="text-gray-600 hover:bg-gray-50 hover:text-gray-900 hover:dark:bg-gray-700 group flex items-center rounded-md px-3 py-2 font-semibold" aria-current="page" href="/automation/166262/leed">...</a> is not clickable at point (1693, 450). Other element would receive the click: <div tabindex="-1" id=":re:" role="tooltip" class="z-40 min-w-[150px] whitespace-pre-wrap rounded-md bg-gray-500 px-4 py-2 text-center text-white dark:text-zinc-100" style="position: absolute; left: 0px; top: 0px; max-width: calc(-40px + 100vw); transform: translate(1674px, 426px); transition-property: opacity; transition-duration: 100ms;">...</div>
  (Session info: chrome=140.0.7339.128); For documentation on this error, please visit: https://www.selenium.dev/documentation/webdriver/troubleshooting/errors#elementclickinterceptedexception
Stacktrace:
	GetHandleVerifier [0x0xee0c13+66051]
	GetHandleVerifier [0x0xee0c54+66116]
	(No symbol) [0x0xcbdb33]
	(No symbol) [0x0xd0dd90]
	(No symbol) [0x0xd0c0f3]
	(No symbol) [0x0xd09ba7]
	(No symbol) [0x0xd08e2d]
	(No symbol) [0x0xcfd335]
	(No symbol) [0x0xd29f8c]
	(No symbol) [0x0xcfcd94]
	(No symbol) [0x0xd2a144]
	(No symbol) [0x0xd4b7f1]
	(No symbol) [0x0xd29d86]
	(No symbol) [0x0xcfb53e]
	(No symbol) [0x0xcfc414]
	GetHandleVerifier [0x0x1128a13+2457603]
	GetHandleVerifier [0x0x11239d2+2437058]
	GetHandleVerifier [0x0xf097f2+232930]
	GetHandleVerifier [0x0xef9a18+167944]
	GetHandleVerifier [0x0xf0092d+196381]
	GetHandleVerifier [0x0xee8ee8+99544]
	GetHandleVerifier [0x0xee9082+99954]
	GetHandleVerifier [0x0xed322a+10266]
	BaseThreadInitThunk [0x0x76395d49+25]
	RtlInitializeExceptionChain [0x0x775ad6db+107]
	RtlGetAppContainerNamedObjectPath [0x0x775ad661+561]

2025-09-19 10:11:32,309 [INFO] novinhub - Selenium robot finished.
2025-09-19 10:11:32,310 [INFO] novinhub - Authenticating Gmail API...
2025-09-19 10:11:32,322 [INFO] novinhub - Gmail service ready.
2025-09-19 10:11:32,322 [INFO] novinhub - Polling for report email for up to 180 seconds...
2025-09-19 10:11:33,410 [INFO] novinhub - No matching messages found for query.
2025-09-19 10:11:44,305 [INFO] novinhub - No matching messages found for query.
2025-09-19 10:11:55,005 [INFO] novinhub - No matching messages found for query.
2025-09-19 10:12:05,588 [INFO] novinhub - No matching messages found for query.
2025-09-19 10:12:15,604 [ERROR] novinhub - Error in full workflow.
Traceback (most recent call last):
  File "D:\MyProject\SalamatSaleDepartment\MainWebSite\WWW\python\ImportPhone_Novinhub.py", line 402, in run_full_workflow
    msg = await asyncio.to_thread(find_recent_email, service)
          ^^^^^^^^^^^^^^^^^^^^^^^^^^^^^^^^^^^^^^^^^^^^^^^^^^^
  File "C:\Users\amira\AppData\Local\Programs\Python\Python313\Lib\asyncio\threads.py", line 25, in to_thread
    return await loop.run_in_executor(None, func_call)
                 ~~~~~~~~~~~~~~~~~~~~^^^^^^^^^^^^^^^^^
  File "C:\Users\amira\AppData\Local\Programs\Python\Python313\Lib\asyncio\base_events.py", line 901, in run_in_executor
    executor.submit(func, *args), loop=self)
    ~~~~~~~~~~~~~~~^^^^^^^^^^^^^
  File "C:\Users\amira\AppData\Local\Programs\Python\Python313\Lib\concurrent\futures\thread.py", line 171, in submit
    raise RuntimeError('cannot schedule new futures after shutdown')
RuntimeError: cannot schedule new futures after shutdown
2025-09-19 10:12:15,626 [INFO] novinhub - Async workflow finished successfully in background.
2025-09-19 10:12:17,007 [INFO] novinhub - Background workflow task scheduled successfully.
2025-09-19 10:12:17,012 [INFO] novinhub - Background task started. Running the async workflow.
2025-09-19 10:12:17,014 [INFO] novinhub - Running robot before checking email...
2025-09-19 10:12:17,015 [INFO] novinhub - Starting Selenium robot...
2025-09-19 10:12:24,476 [INFO] novinhub - Opened start URL: https://app.novinhub.com/login?redirect=%2Fdashboard
2025-09-19 10:12:24,476 [INFO] novinhub - Attempting to log in...
2025-09-19 10:12:26,669 [INFO] novinhub - Login form submitted.
2025-09-19 10:12:29,239 [INFO] novinhub - Login successful, dashboard loaded.
2025-09-19 10:12:29,240 [INFO] novinhub - Navigating to automation page...
2025-09-19 10:12:29,329 [INFO] novinhub - Navigating to export numbers tab...
2025-09-19 10:12:30,373 [ERROR] novinhub - An error occurred during Selenium robot execution: Message: element click intercepted: Element <a class="text-gray-600 hover:bg-gray-50 hover:text-gray-900 hover:dark:bg-gray-700 group flex items-center rounded-md px-3 py-2 font-semibold" aria-current="page" href="/automation/166262/leed">...</a> is not clickable at point (1698, 449). Other element would receive the click: <div tabindex="-1" id=":re:" role="tooltip" class="z-40 min-w-[150px] whitespace-pre-wrap rounded-md bg-gray-500 px-4 py-2 text-center text-white dark:text-zinc-100" style="position: absolute; left: 0px; top: 0px; max-width: calc(-40px + 100vw); transform: translate(1679.2px, 426.4px); transition-property: opacity; transition-duration: 100ms;">...</div>
  (Session info: chrome=140.0.7339.128); For documentation on this error, please visit: https://www.selenium.dev/documentation/webdriver/troubleshooting/errors#elementclickinterceptedexception
Stacktrace:
	GetHandleVerifier [0x0xee0c13+66051]
	GetHandleVerifier [0x0xee0c54+66116]
	(No symbol) [0x0xcbdb33]
	(No symbol) [0x0xd0dd90]
	(No symbol) [0x0xd0c0f3]
	(No symbol) [0x0xd09ba7]
	(No symbol) [0x0xd08e2d]
	(No symbol) [0x0xcfd335]
	(No symbol) [0x0xd29f8c]
	(No symbol) [0x0xcfcd94]
	(No symbol) [0x0xd2a144]
	(No symbol) [0x0xd4b7f1]
	(No symbol) [0x0xd29d86]
	(No symbol) [0x0xcfb53e]
	(No symbol) [0x0xcfc414]
	GetHandleVerifier [0x0x1128a13+2457603]
	GetHandleVerifier [0x0x11239d2+2437058]
	GetHandleVerifier [0x0xf097f2+232930]
	GetHandleVerifier [0x0xef9a18+167944]
	GetHandleVerifier [0x0xf0092d+196381]
	GetHandleVerifier [0x0xee8ee8+99544]
	GetHandleVerifier [0x0xee9082+99954]
	GetHandleVerifier [0x0xed322a+10266]
	BaseThreadInitThunk [0x0x76395d49+25]
	RtlInitializeExceptionChain [0x0x775ad6db+107]
	RtlGetAppContainerNamedObjectPath [0x0x775ad661+561]
Traceback (most recent call last):
  File "D:\MyProject\SalamatSaleDepartment\MainWebSite\WWW\python\ImportPhone_Novinhub.py", line 349, in run_robot
    wait.until(EC.presence_of_element_located((By.CSS_SELECTOR, export_tab_selector))).click()
    ~~~~~~~~~~~~~~~~~~~~~~~~~~~~~~~~~~~~~~~~~~~~~~~~~~~~~~~~~~~~~~~~~~~~~~~~~~~~~~~~~~~~~~~~^^
  File "C:\Users\amira\AppData\Local\Programs\Python\Python313\Lib\site-packages\selenium\webdriver\remote\webelement.py", line 120, in click
    self._execute(Command.CLICK_ELEMENT)
    ~~~~~~~~~~~~~^^^^^^^^^^^^^^^^^^^^^^^
  File "C:\Users\amira\AppData\Local\Programs\Python\Python313\Lib\site-packages\selenium\webdriver\remote\webelement.py", line 573, in _execute
    return self._parent.execute(command, params)
           ~~~~~~~~~~~~~~~~~~~~^^^^^^^^^^^^^^^^^
  File "C:\Users\amira\AppData\Local\Programs\Python\Python313\Lib\site-packages\selenium\webdriver\remote\webdriver.py", line 458, in execute
    self.error_handler.check_response(response)
    ~~~~~~~~~~~~~~~~~~~~~~~~~~~~~~~~~^^^^^^^^^^
  File "C:\Users\amira\AppData\Local\Programs\Python\Python313\Lib\site-packages\selenium\webdriver\remote\errorhandler.py", line 232, in check_response
    raise exception_class(message, screen, stacktrace)
selenium.common.exceptions.ElementClickInterceptedException: Message: element click intercepted: Element <a class="text-gray-600 hover:bg-gray-50 hover:text-gray-900 hover:dark:bg-gray-700 group flex items-center rounded-md px-3 py-2 font-semibold" aria-current="page" href="/automation/166262/leed">...</a> is not clickable at point (1698, 449). Other element would receive the click: <div tabindex="-1" id=":re:" role="tooltip" class="z-40 min-w-[150px] whitespace-pre-wrap rounded-md bg-gray-500 px-4 py-2 text-center text-white dark:text-zinc-100" style="position: absolute; left: 0px; top: 0px; max-width: calc(-40px + 100vw); transform: translate(1679.2px, 426.4px); transition-property: opacity; transition-duration: 100ms;">...</div>
  (Session info: chrome=140.0.7339.128); For documentation on this error, please visit: https://www.selenium.dev/documentation/webdriver/troubleshooting/errors#elementclickinterceptedexception
Stacktrace:
	GetHandleVerifier [0x0xee0c13+66051]
	GetHandleVerifier [0x0xee0c54+66116]
	(No symbol) [0x0xcbdb33]
	(No symbol) [0x0xd0dd90]
	(No symbol) [0x0xd0c0f3]
	(No symbol) [0x0xd09ba7]
	(No symbol) [0x0xd08e2d]
	(No symbol) [0x0xcfd335]
	(No symbol) [0x0xd29f8c]
	(No symbol) [0x0xcfcd94]
	(No symbol) [0x0xd2a144]
	(No symbol) [0x0xd4b7f1]
	(No symbol) [0x0xd29d86]
	(No symbol) [0x0xcfb53e]
	(No symbol) [0x0xcfc414]
	GetHandleVerifier [0x0x1128a13+2457603]
	GetHandleVerifier [0x0x11239d2+2437058]
	GetHandleVerifier [0x0xf097f2+232930]
	GetHandleVerifier [0x0xef9a18+167944]
	GetHandleVerifier [0x0xf0092d+196381]
	GetHandleVerifier [0x0xee8ee8+99544]
	GetHandleVerifier [0x0xee9082+99954]
	GetHandleVerifier [0x0xed322a+10266]
	BaseThreadInitThunk [0x0x76395d49+25]
	RtlInitializeExceptionChain [0x0x775ad6db+107]
	RtlGetAppContainerNamedObjectPath [0x0x775ad661+561]

2025-09-19 10:12:32,504 [INFO] novinhub - Selenium robot finished.
2025-09-19 10:12:32,505 [INFO] novinhub - Authenticating Gmail API...
2025-09-19 10:12:32,508 [INFO] novinhub - Gmail service ready.
2025-09-19 10:12:32,509 [INFO] novinhub - Polling for report email for up to 180 seconds...
2025-09-19 10:12:33,460 [INFO] novinhub - No matching messages found for query.
2025-09-19 10:12:43,872 [INFO] novinhub - No matching messages found for query.
2025-09-19 10:12:54,270 [INFO] novinhub - No matching messages found for query.
2025-09-19 10:13:04,679 [INFO] novinhub - No matching messages found for query.
2025-09-19 10:13:15,088 [INFO] novinhub - No matching messages found for query.
2025-09-19 10:13:25,573 [INFO] novinhub - No matching messages found for query.
2025-09-19 10:13:35,998 [INFO] novinhub - No matching messages found for query.
2025-09-19 10:13:46,403 [INFO] novinhub - No matching messages found for query.
2025-09-19 10:13:56,815 [INFO] novinhub - No matching messages found for query.
2025-09-19 10:14:07,237 [INFO] novinhub - No matching messages found for query.
2025-09-19 10:14:17,638 [INFO] novinhub - No matching messages found for query.
2025-09-19 10:14:28,074 [INFO] novinhub - No matching messages found for query.
2025-09-19 10:14:38,483 [INFO] novinhub - No matching messages found for query.
2025-09-19 10:14:48,913 [INFO] novinhub - No matching messages found for query.
2025-09-19 10:14:59,329 [INFO] novinhub - No matching messages found for query.
2025-09-19 10:15:09,818 [INFO] novinhub - No matching messages found for query.
2025-09-19 10:15:20,238 [INFO] novinhub - No matching messages found for query.
2025-09-19 10:15:30,649 [INFO] novinhub - No matching messages found for query.
2025-09-19 10:15:41,065 [INFO] novinhub - No matching messages found for query.
2025-09-19 10:15:41,065 [WARNING] novinhub - Timeout while waiting for report email.
2025-09-19 10:15:41,067 [INFO] novinhub - Async workflow finished successfully in background.
2025-09-19 10:32:19,719 [INFO] novinhub - Background workflow task scheduled successfully.
2025-09-19 10:32:19,726 [INFO] novinhub - Background task started. Running the async workflow.
2025-09-19 10:32:19,727 [INFO] novinhub - Running robot before checking email...
2025-09-19 10:32:19,729 [INFO] novinhub - Starting Selenium robot...
2025-09-19 10:32:23,682 [INFO] novinhub - Opened start URL: https://app.novinhub.com/login?redirect=%2Fdashboard
2025-09-19 10:32:23,682 [INFO] novinhub - Attempting to log in...
2025-09-19 10:32:27,112 [INFO] novinhub - Login form submitted. Waiting to see if login is successful or if a CAPTCHA appears...
2025-09-19 10:32:27,112 [INFO] novinhub - Waiting for dashboard to load...
2025-09-19 10:32:29,667 [INFO] novinhub - Login successful, dashboard loaded.
2025-09-19 10:32:29,673 [INFO] novinhub - Login successful, dashboard loaded.
2025-09-19 10:32:29,673 [INFO] novinhub - Navigating to automation page...
2025-09-19 10:32:29,754 [INFO] novinhub - Navigating to export numbers tab...
2025-09-19 10:32:30,863 [ERROR] novinhub - An error occurred during Selenium robot execution: Message: element click intercepted: Element <a class="text-gray-600 hover:bg-gray-50 hover:text-gray-900 hover:dark:bg-gray-700 group flex items-center rounded-md px-3 py-2 font-semibold" aria-current="page" href="/automation/166262/leed">...</a> is not clickable at point (1698, 449). Other element would receive the click: <div tabindex="-1" id=":re:" role="tooltip" class="z-40 min-w-[150px] whitespace-pre-wrap rounded-md bg-gray-500 px-4 py-2 text-center text-white dark:text-zinc-100" style="position: absolute; left: 0px; top: 0px; max-width: calc(-40px + 100vw); transform: translate(1679.2px, 426.4px); transition-property: opacity; transition-duration: 100ms;">...</div>
  (Session info: chrome=140.0.7339.128); For documentation on this error, please visit: https://www.selenium.dev/documentation/webdriver/troubleshooting/errors#elementclickinterceptedexception
Stacktrace:
	GetHandleVerifier [0x0x430c13+66051]
	GetHandleVerifier [0x0x430c54+66116]
	(No symbol) [0x0x20db33]
	(No symbol) [0x0x25dd90]
	(No symbol) [0x0x25c0f3]
	(No symbol) [0x0x259ba7]
	(No symbol) [0x0x258e2d]
	(No symbol) [0x0x24d335]
	(No symbol) [0x0x279f8c]
	(No symbol) [0x0x24cd94]
	(No symbol) [0x0x27a144]
	(No symbol) [0x0x29b7f1]
	(No symbol) [0x0x279d86]
	(No symbol) [0x0x24b53e]
	(No symbol) [0x0x24c414]
	GetHandleVerifier [0x0x678a13+2457603]
	GetHandleVerifier [0x0x6739d2+2437058]
	GetHandleVerifier [0x0x4597f2+232930]
	GetHandleVerifier [0x0x449a18+167944]
	GetHandleVerifier [0x0x45092d+196381]
	GetHandleVerifier [0x0x438ee8+99544]
	GetHandleVerifier [0x0x439082+99954]
	GetHandleVerifier [0x0x42322a+10266]
	BaseThreadInitThunk [0x0x76395d49+25]
	RtlInitializeExceptionChain [0x0x775ad6db+107]
	RtlGetAppContainerNamedObjectPath [0x0x775ad661+561]
Traceback (most recent call last):
  File "D:\MyProject\SalamatSaleDepartment\MainWebSite\WWW\python\ImportPhone_Novinhub.py", line 431, in run_robot
    wait.until(EC.presence_of_element_located((By.CSS_SELECTOR, export_tab_selector))).click()
    ~~~~~~~~~~~~~~~~~~~~~~~~~~~~~~~~~~~~~~~~~~~~~~~~~~~~~~~~~~~~~~~~~~~~~~~~~~~~~~~~~~~~~~~~^^
  File "C:\Users\amira\AppData\Local\Programs\Python\Python313\Lib\site-packages\selenium\webdriver\remote\webelement.py", line 120, in click
    self._execute(Command.CLICK_ELEMENT)
    ~~~~~~~~~~~~~^^^^^^^^^^^^^^^^^^^^^^^
  File "C:\Users\amira\AppData\Local\Programs\Python\Python313\Lib\site-packages\selenium\webdriver\remote\webelement.py", line 573, in _execute
    return self._parent.execute(command, params)
           ~~~~~~~~~~~~~~~~~~~~^^^^^^^^^^^^^^^^^
  File "C:\Users\amira\AppData\Local\Programs\Python\Python313\Lib\site-packages\selenium\webdriver\remote\webdriver.py", line 458, in execute
    self.error_handler.check_response(response)
    ~~~~~~~~~~~~~~~~~~~~~~~~~~~~~~~~~^^^^^^^^^^
  File "C:\Users\amira\AppData\Local\Programs\Python\Python313\Lib\site-packages\selenium\webdriver\remote\errorhandler.py", line 232, in check_response
    raise exception_class(message, screen, stacktrace)
selenium.common.exceptions.ElementClickInterceptedException: Message: element click intercepted: Element <a class="text-gray-600 hover:bg-gray-50 hover:text-gray-900 hover:dark:bg-gray-700 group flex items-center rounded-md px-3 py-2 font-semibold" aria-current="page" href="/automation/166262/leed">...</a> is not clickable at point (1698, 449). Other element would receive the click: <div tabindex="-1" id=":re:" role="tooltip" class="z-40 min-w-[150px] whitespace-pre-wrap rounded-md bg-gray-500 px-4 py-2 text-center text-white dark:text-zinc-100" style="position: absolute; left: 0px; top: 0px; max-width: calc(-40px + 100vw); transform: translate(1679.2px, 426.4px); transition-property: opacity; transition-duration: 100ms;">...</div>
  (Session info: chrome=140.0.7339.128); For documentation on this error, please visit: https://www.selenium.dev/documentation/webdriver/troubleshooting/errors#elementclickinterceptedexception
Stacktrace:
	GetHandleVerifier [0x0x430c13+66051]
	GetHandleVerifier [0x0x430c54+66116]
	(No symbol) [0x0x20db33]
	(No symbol) [0x0x25dd90]
	(No symbol) [0x0x25c0f3]
	(No symbol) [0x0x259ba7]
	(No symbol) [0x0x258e2d]
	(No symbol) [0x0x24d335]
	(No symbol) [0x0x279f8c]
	(No symbol) [0x0x24cd94]
	(No symbol) [0x0x27a144]
	(No symbol) [0x0x29b7f1]
	(No symbol) [0x0x279d86]
	(No symbol) [0x0x24b53e]
	(No symbol) [0x0x24c414]
	GetHandleVerifier [0x0x678a13+2457603]
	GetHandleVerifier [0x0x6739d2+2437058]
	GetHandleVerifier [0x0x4597f2+232930]
	GetHandleVerifier [0x0x449a18+167944]
	GetHandleVerifier [0x0x45092d+196381]
	GetHandleVerifier [0x0x438ee8+99544]
	GetHandleVerifier [0x0x439082+99954]
	GetHandleVerifier [0x0x42322a+10266]
	BaseThreadInitThunk [0x0x76395d49+25]
	RtlInitializeExceptionChain [0x0x775ad6db+107]
	RtlGetAppContainerNamedObjectPath [0x0x775ad661+561]

2025-09-19 10:32:33,132 [INFO] novinhub - Selenium robot finished.
2025-09-19 10:32:33,132 [INFO] novinhub - Authenticating Gmail API...
2025-09-19 10:32:33,138 [INFO] novinhub - Gmail service ready.
2025-09-19 10:32:33,138 [INFO] novinhub - Polling for report email for up to 180 seconds...
2025-09-19 10:32:35,169 [INFO] novinhub - No matching messages found for query.
2025-09-19 10:32:45,591 [INFO] novinhub - No matching messages found for query.
2025-09-19 10:32:55,608 [ERROR] novinhub - Error in full workflow.
Traceback (most recent call last):
  File "D:\MyProject\SalamatSaleDepartment\MainWebSite\WWW\python\ImportPhone_Novinhub.py", line 484, in run_full_workflow
    msg = await asyncio.to_thread(find_recent_email, service)
          ^^^^^^^^^^^^^^^^^^^^^^^^^^^^^^^^^^^^^^^^^^^^^^^^^^^
  File "C:\Users\amira\AppData\Local\Programs\Python\Python313\Lib\asyncio\threads.py", line 25, in to_thread
    return await loop.run_in_executor(None, func_call)
                 ~~~~~~~~~~~~~~~~~~~~^^^^^^^^^^^^^^^^^
  File "C:\Users\amira\AppData\Local\Programs\Python\Python313\Lib\asyncio\base_events.py", line 901, in run_in_executor
    executor.submit(func, *args), loop=self)
    ~~~~~~~~~~~~~~~^^^^^^^^^^^^^
  File "C:\Users\amira\AppData\Local\Programs\Python\Python313\Lib\concurrent\futures\thread.py", line 171, in submit
    raise RuntimeError('cannot schedule new futures after shutdown')
RuntimeError: cannot schedule new futures after shutdown
2025-09-19 10:32:55,613 [INFO] novinhub - Async workflow finished successfully in background.
2025-09-19 10:45:12,075 [INFO] novinhub - Background workflow task scheduled successfully.
2025-09-19 10:45:12,081 [INFO] novinhub - Background task started. Running the async workflow.
2025-09-19 10:45:12,083 [INFO] novinhub - Running robot before checking email...
2025-09-19 10:45:12,084 [INFO] novinhub - Starting Selenium robot...
2025-09-19 10:45:15,107 [ERROR] novinhub - An error occurred during Selenium robot execution: name 'stealth' is not defined
Traceback (most recent call last):
  File "D:\MyProject\SalamatSaleDepartment\MainWebSite\WWW\python\ImportPhone_Novinhub.py", line 386, in run_robot
    driver, wait = prepare_chrome_driver(START_URL, profile_path, showBrowser=False)
                   ~~~~~~~~~~~~~~~~~~~~~^^^^^^^^^^^^^^^^^^^^^^^^^^^^^^^^^^^^^^^^^^^^
  File "D:\MyProject\SalamatSaleDepartment\MainWebSite\WWW\python\ImportPhone_Novinhub.py", line 364, in prepare_chrome_driver
    stealth(driver,
    ^^^^^^^
NameError: name 'stealth' is not defined
2025-09-19 10:45:45,111 [INFO] novinhub - Selenium robot finished.
2025-09-19 10:45:45,111 [INFO] novinhub - Authenticating Gmail API...
2025-09-19 10:45:45,116 [INFO] novinhub - Gmail service ready.
2025-09-19 10:45:45,116 [INFO] novinhub - Polling for report email for up to 180 seconds...
2025-09-19 10:45:46,341 [INFO] novinhub - No matching messages found for query.
2025-09-19 10:45:56,351 [ERROR] novinhub - Error in full workflow.
Traceback (most recent call last):
  File "D:\MyProject\SalamatSaleDepartment\MainWebSite\WWW\python\ImportPhone_Novinhub.py", line 490, in run_full_workflow
    msg = await asyncio.to_thread(find_recent_email, service)
          ^^^^^^^^^^^^^^^^^^^^^^^^^^^^^^^^^^^^^^^^^^^^^^^^^^^
  File "C:\Users\amira\AppData\Local\Programs\Python\Python313\Lib\asyncio\threads.py", line 25, in to_thread
    return await loop.run_in_executor(None, func_call)
                 ~~~~~~~~~~~~~~~~~~~~^^^^^^^^^^^^^^^^^
  File "C:\Users\amira\AppData\Local\Programs\Python\Python313\Lib\asyncio\base_events.py", line 901, in run_in_executor
    executor.submit(func, *args), loop=self)
    ~~~~~~~~~~~~~~~^^^^^^^^^^^^^
  File "C:\Users\amira\AppData\Local\Programs\Python\Python313\Lib\concurrent\futures\thread.py", line 171, in submit
    raise RuntimeError('cannot schedule new futures after shutdown')
RuntimeError: cannot schedule new futures after shutdown
2025-09-19 10:45:56,354 [INFO] novinhub - Async workflow finished successfully in background.
2025-09-19 10:46:59,208 [INFO] novinhub - Background workflow task scheduled successfully.
2025-09-19 10:46:59,214 [INFO] novinhub - Background task started. Running the async workflow.
2025-09-19 10:46:59,215 [INFO] novinhub - Running robot before checking email...
2025-09-19 10:46:59,217 [INFO] novinhub - Starting Selenium robot...
2025-09-19 10:47:02,218 [ERROR] novinhub - An error occurred during Selenium robot execution: name 'stealth' is not defined
Traceback (most recent call last):
  File "D:\MyProject\SalamatSaleDepartment\MainWebSite\WWW\python\ImportPhone_Novinhub.py", line 386, in run_robot
    driver, wait = prepare_chrome_driver(START_URL, profile_path, showBrowser=False)
                   ~~~~~~~~~~~~~~~~~~~~~^^^^^^^^^^^^^^^^^^^^^^^^^^^^^^^^^^^^^^^^^^^^
  File "D:\MyProject\SalamatSaleDepartment\MainWebSite\WWW\python\ImportPhone_Novinhub.py", line 364, in prepare_chrome_driver
    stealth(driver,
    ^^^^^^^
NameError: name 'stealth' is not defined
2025-09-19 10:47:32,220 [INFO] novinhub - Selenium robot finished.
2025-09-19 10:47:32,220 [INFO] novinhub - Authenticating Gmail API...
2025-09-19 10:47:32,224 [INFO] novinhub - Gmail service ready.
2025-09-19 10:47:32,225 [INFO] novinhub - Polling for report email for up to 180 seconds...
2025-09-19 10:47:33,277 [INFO] novinhub - No matching messages found for query.
2025-09-19 10:47:43,286 [ERROR] novinhub - Error in full workflow.
Traceback (most recent call last):
  File "D:\MyProject\SalamatSaleDepartment\MainWebSite\WWW\python\ImportPhone_Novinhub.py", line 490, in run_full_workflow
    while True:
              ^
  File "C:\Users\amira\AppData\Local\Programs\Python\Python313\Lib\asyncio\threads.py", line 25, in to_thread
    return await loop.run_in_executor(None, func_call)
                 ~~~~~~~~~~~~~~~~~~~~^^^^^^^^^^^^^^^^^
  File "C:\Users\amira\AppData\Local\Programs\Python\Python313\Lib\asyncio\base_events.py", line 901, in run_in_executor
    executor.submit(func, *args), loop=self)
    ~~~~~~~~~~~~~~~^^^^^^^^^^^^^
  File "C:\Users\amira\AppData\Local\Programs\Python\Python313\Lib\concurrent\futures\thread.py", line 171, in submit
    raise RuntimeError('cannot schedule new futures after shutdown')
RuntimeError: cannot schedule new futures after shutdown
2025-09-19 10:47:43,302 [INFO] novinhub - Async workflow finished successfully in background.
2025-09-19 10:47:44,680 [INFO] novinhub - Background workflow task scheduled successfully.
2025-09-19 10:47:44,684 [INFO] novinhub - Background task started. Running the async workflow.
2025-09-19 10:47:44,685 [INFO] novinhub - Running robot before checking email...
2025-09-19 10:47:44,687 [INFO] novinhub - Starting Selenium robot...
2025-09-19 10:49:27,587 [INFO] novinhub - Background workflow task scheduled successfully.
2025-09-19 10:49:27,595 [INFO] novinhub - Background task started. Running the async workflow.
2025-09-19 10:49:27,596 [INFO] novinhub - Running robot before checking email...
2025-09-19 10:49:27,598 [INFO] novinhub - Starting Selenium robot...
2025-09-19 10:49:31,836 [INFO] novinhub - Opened start URL: https://app.novinhub.com/login?redirect=%2Fdashboard
2025-09-19 10:49:31,836 [INFO] novinhub - Attempting to log in...
2025-09-19 10:50:12,114 [ERROR] novinhub - An error occurred during Selenium robot execution: Message: 
Stacktrace:
	GetHandleVerifier [0x0x430c13+66051]
	GetHandleVerifier [0x0x430c54+66116]
	(No symbol) [0x0x20db33]
	(No symbol) [0x0x2578a8]
	(No symbol) [0x0x257c4b]
	(No symbol) [0x0x29e0a2]
	(No symbol) [0x0x279fd4]
	(No symbol) [0x0x29b7f1]
	(No symbol) [0x0x279d86]
	(No symbol) [0x0x24b53e]
	(No symbol) [0x0x24c414]
	GetHandleVerifier [0x0x678a13+2457603]
	GetHandleVerifier [0x0x6739d2+2437058]
	GetHandleVerifier [0x0x4597f2+232930]
	GetHandleVerifier [0x0x449a18+167944]
	GetHandleVerifier [0x0x45092d+196381]
	GetHandleVerifier [0x0x438ee8+99544]
	GetHandleVerifier [0x0x439082+99954]
	GetHandleVerifier [0x0x42322a+10266]
	BaseThreadInitThunk [0x0x76395d49+25]
	RtlInitializeExceptionChain [0x0x775ad6db+107]
	RtlGetAppContainerNamedObjectPath [0x0x775ad661+561]
Traceback (most recent call last):
  File "D:\MyProject\SalamatSaleDepartment\MainWebSite\WWW\python\ImportPhone_Novinhub.py", line 393, in run_robot
    email_input = wait.until(EC.presence_of_element_located((By.CSS_SELECTOR, "input[name='email']")))
  File "C:\Users\amira\AppData\Local\Programs\Python\Python313\Lib\site-packages\selenium\webdriver\support\wait.py", line 138, in until
    raise TimeoutException(message, screen, stacktrace)
selenium.common.exceptions.TimeoutException: Message: 
Stacktrace:
	GetHandleVerifier [0x0x430c13+66051]
	GetHandleVerifier [0x0x430c54+66116]
	(No symbol) [0x0x20db33]
	(No symbol) [0x0x2578a8]
	(No symbol) [0x0x257c4b]
	(No symbol) [0x0x29e0a2]
	(No symbol) [0x0x279fd4]
	(No symbol) [0x0x29b7f1]
	(No symbol) [0x0x279d86]
	(No symbol) [0x0x24b53e]
	(No symbol) [0x0x24c414]
	GetHandleVerifier [0x0x678a13+2457603]
	GetHandleVerifier [0x0x6739d2+2437058]
	GetHandleVerifier [0x0x4597f2+232930]
	GetHandleVerifier [0x0x449a18+167944]
	GetHandleVerifier [0x0x45092d+196381]
	GetHandleVerifier [0x0x438ee8+99544]
	GetHandleVerifier [0x0x439082+99954]
	GetHandleVerifier [0x0x42322a+10266]
	BaseThreadInitThunk [0x0x76395d49+25]
	RtlInitializeExceptionChain [0x0x775ad6db+107]
	RtlGetAppContainerNamedObjectPath [0x0x775ad661+561]

2025-09-19 10:50:44,228 [INFO] novinhub - Selenium robot finished.
2025-09-19 10:50:44,229 [INFO] novinhub - Authenticating Gmail API...
2025-09-19 10:50:44,232 [INFO] novinhub - Gmail service ready.
2025-09-19 10:50:44,233 [INFO] novinhub - Polling for report email for up to 180 seconds...
2025-09-19 10:50:45,261 [INFO] novinhub - No matching messages found for query.
2025-09-19 10:50:55,670 [INFO] novinhub - No matching messages found for query.
2025-09-19 10:51:06,093 [INFO] novinhub - No matching messages found for query.
2025-09-19 10:51:16,094 [ERROR] novinhub - Error in full workflow.
Traceback (most recent call last):
  File "D:\MyProject\SalamatSaleDepartment\MainWebSite\WWW\python\ImportPhone_Novinhub.py", line 491, in run_full_workflow
    return result
  File "C:\Users\amira\AppData\Local\Programs\Python\Python313\Lib\asyncio\threads.py", line 25, in to_thread
    return await loop.run_in_executor(None, func_call)
                 ~~~~~~~~~~~~~~~~~~~~^^^^^^^^^^^^^^^^^
  File "C:\Users\amira\AppData\Local\Programs\Python\Python313\Lib\asyncio\base_events.py", line 901, in run_in_executor
    executor.submit(func, *args), loop=self)
    ~~~~~~~~~~~~~~~^^^^^^^^^^^^^
  File "C:\Users\amira\AppData\Local\Programs\Python\Python313\Lib\concurrent\futures\thread.py", line 171, in submit
    raise RuntimeError('cannot schedule new futures after shutdown')
RuntimeError: cannot schedule new futures after shutdown
2025-09-19 10:51:16,110 [INFO] novinhub - Async workflow finished successfully in background.
2025-09-19 10:51:25,332 [INFO] novinhub - Background workflow task scheduled successfully.
2025-09-19 10:51:25,337 [INFO] novinhub - Background task started. Running the async workflow.
2025-09-19 10:51:25,338 [INFO] novinhub - Running robot before checking email...
2025-09-19 10:51:25,339 [INFO] novinhub - Starting Selenium robot...
2025-09-19 10:51:28,612 [INFO] novinhub - Opened start URL: https://app.novinhub.com/login?redirect=%2Fdashboard
2025-09-19 10:51:28,612 [INFO] novinhub - Attempting to log in...
2025-09-19 10:51:58,820 [ERROR] novinhub - An error occurred during Selenium robot execution: Message: invalid session id: session deleted as the browser has closed the connection
from disconnected: not connected to DevTools
  (Session info: chrome=140.0.7339.128); For documentation on this error, please visit: https://www.selenium.dev/documentation/webdriver/troubleshooting/errors#invalidsessionidexception
Stacktrace:
	GetHandleVerifier [0x0x430c13+66051]
	GetHandleVerifier [0x0x430c54+66116]
	(No symbol) [0x0x20db33]
	(No symbol) [0x0x1fcfd0]
	(No symbol) [0x0x21b6db]
	(No symbol) [0x0x2809b5]
	(No symbol) [0x0x29b109]
	(No symbol) [0x0x279d86]
	(No symbol) [0x0x24b53e]
	(No symbol) [0x0x24c414]
	GetHandleVerifier [0x0x678a13+2457603]
	GetHandleVerifier [0x0x6739d2+2437058]
	GetHandleVerifier [0x0x4597f2+232930]
	GetHandleVerifier [0x0x449a18+167944]
	GetHandleVerifier [0x0x45092d+196381]
	GetHandleVerifier [0x0x438ee8+99544]
	GetHandleVerifier [0x0x439082+99954]
	GetHandleVerifier [0x0x42322a+10266]
	BaseThreadInitThunk [0x0x76395d49+25]
	RtlInitializeExceptionChain [0x0x775ad6db+107]
	RtlGetAppContainerNamedObjectPath [0x0x775ad661+561]
Traceback (most recent call last):
  File "D:\MyProject\SalamatSaleDepartment\MainWebSite\WWW\python\ImportPhone_Novinhub.py", line 386, in run_robot
    email_input = wait.until(EC.presence_of_element_located((By.CSS_SELECTOR, "input[name='email']")))
  File "C:\Users\amira\AppData\Local\Programs\Python\Python313\Lib\site-packages\selenium\webdriver\support\wait.py", line 129, in until
    value = method(self._driver)
  File "C:\Users\amira\AppData\Local\Programs\Python\Python313\Lib\site-packages\selenium\webdriver\support\expected_conditions.py", line 104, in _predicate
    return driver.find_element(*locator)
           ~~~~~~~~~~~~~~~~~~~^^^^^^^^^^
  File "C:\Users\amira\AppData\Local\Programs\Python\Python313\Lib\site-packages\selenium\webdriver\remote\webdriver.py", line 926, in find_element
    return self.execute(Command.FIND_ELEMENT, {"using": by, "value": value})["value"]
           ~~~~~~~~~~~~^^^^^^^^^^^^^^^^^^^^^^^^^^^^^^^^^^^^^^^^^^^^^^^^^^^^^
  File "C:\Users\amira\AppData\Local\Programs\Python\Python313\Lib\site-packages\selenium\webdriver\remote\webdriver.py", line 458, in execute
    self.error_handler.check_response(response)
    ~~~~~~~~~~~~~~~~~~~~~~~~~~~~~~~~~^^^^^^^^^^
  File "C:\Users\amira\AppData\Local\Programs\Python\Python313\Lib\site-packages\selenium\webdriver\remote\errorhandler.py", line 232, in check_response
    raise exception_class(message, screen, stacktrace)
selenium.common.exceptions.InvalidSessionIdException: Message: invalid session id: session deleted as the browser has closed the connection
from disconnected: not connected to DevTools
  (Session info: chrome=140.0.7339.128); For documentation on this error, please visit: https://www.selenium.dev/documentation/webdriver/troubleshooting/errors#invalidsessionidexception
Stacktrace:
	GetHandleVerifier [0x0x430c13+66051]
	GetHandleVerifier [0x0x430c54+66116]
	(No symbol) [0x0x20db33]
	(No symbol) [0x0x1fcfd0]
	(No symbol) [0x0x21b6db]
	(No symbol) [0x0x2809b5]
	(No symbol) [0x0x29b109]
	(No symbol) [0x0x279d86]
	(No symbol) [0x0x24b53e]
	(No symbol) [0x0x24c414]
	GetHandleVerifier [0x0x678a13+2457603]
	GetHandleVerifier [0x0x6739d2+2437058]
	GetHandleVerifier [0x0x4597f2+232930]
	GetHandleVerifier [0x0x449a18+167944]
	GetHandleVerifier [0x0x45092d+196381]
	GetHandleVerifier [0x0x438ee8+99544]
	GetHandleVerifier [0x0x439082+99954]
	GetHandleVerifier [0x0x42322a+10266]
	BaseThreadInitThunk [0x0x76395d49+25]
	RtlInitializeExceptionChain [0x0x775ad6db+107]
	RtlGetAppContainerNamedObjectPath [0x0x775ad661+561]

2025-09-19 10:52:45,234 [INFO] novinhub - Selenium robot finished.
2025-09-19 10:52:45,235 [INFO] novinhub - Authenticating Gmail API...
2025-09-19 10:52:45,240 [INFO] novinhub - Gmail service ready.
2025-09-19 10:52:45,240 [INFO] novinhub - Polling for report email for up to 180 seconds...
2025-09-19 10:52:46,299 [INFO] novinhub - No matching messages found for query.
2025-09-19 10:52:56,754 [INFO] novinhub - No matching messages found for query.
2025-09-19 10:53:07,197 [INFO] novinhub - No matching messages found for query.
2025-09-19 10:53:17,618 [INFO] novinhub - No matching messages found for query.
2025-09-19 10:53:27,628 [ERROR] novinhub - Error in full workflow.
Traceback (most recent call last):
  File "D:\MyProject\SalamatSaleDepartment\MainWebSite\WWW\python\ImportPhone_Novinhub.py", line 484, in run_full_workflow
  File "C:\Users\amira\AppData\Local\Programs\Python\Python313\Lib\asyncio\threads.py", line 25, in to_thread
    return await loop.run_in_executor(None, func_call)
                 ~~~~~~~~~~~~~~~~~~~~^^^^^^^^^^^^^^^^^
  File "C:\Users\amira\AppData\Local\Programs\Python\Python313\Lib\asyncio\base_events.py", line 901, in run_in_executor
    executor.submit(func, *args), loop=self)
    ~~~~~~~~~~~~~~~^^^^^^^^^^^^^
  File "C:\Users\amira\AppData\Local\Programs\Python\Python313\Lib\concurrent\futures\thread.py", line 171, in submit
    raise RuntimeError('cannot schedule new futures after shutdown')
RuntimeError: cannot schedule new futures after shutdown
2025-09-19 10:53:27,642 [INFO] novinhub - Async workflow finished successfully in background.
2025-09-19 10:55:33,879 [INFO] novinhub - Background workflow task scheduled successfully.
2025-09-19 10:55:33,885 [INFO] novinhub - Background task started. Running the async workflow.
2025-09-19 10:55:33,886 [INFO] novinhub - Running robot before checking email...
2025-09-19 10:55:33,888 [INFO] novinhub - Starting Selenium robot...
2025-09-19 10:55:37,604 [INFO] novinhub - Opened start URL: https://app.novinhub.com/login?redirect=%2Fdashboard
2025-09-19 10:55:39,148 [INFO] novinhub - User is already logged in.
2025-09-19 10:55:39,149 [INFO] novinhub - Navigating to automation page...
2025-09-19 10:55:39,749 [INFO] novinhub - Navigating to export numbers tab...
2025-09-19 10:55:42,869 [INFO] novinhub - Clicking 'Export' button...
2025-09-19 10:55:42,953 [INFO] novinhub - Filling out the export modal form...
2025-09-19 10:55:43,101 [INFO] novinhub - Submitting the export request...
2025-09-19 10:55:43,152 [INFO] novinhub - Selenium robot has successfully requested the Excel file.
2025-09-19 10:55:45,284 [INFO] novinhub - Selenium robot finished.
2025-09-19 10:55:45,285 [INFO] novinhub - Authenticating Gmail API...
2025-09-19 10:55:45,289 [INFO] novinhub - Gmail service ready.
2025-09-19 10:55:45,289 [INFO] novinhub - Polling for report email for up to 180 seconds...
2025-09-19 10:55:46,240 [INFO] novinhub - No matching messages found for query.
2025-09-19 10:55:56,644 [INFO] novinhub - No matching messages found for query.
2025-09-19 10:56:07,045 [INFO] novinhub - No matching messages found for query.
2025-09-19 10:56:17,744 [INFO] novinhub - No matching messages found for query.
2025-09-19 10:56:28,157 [INFO] novinhub - No matching messages found for query.
2025-09-19 10:56:38,555 [INFO] novinhub - No matching messages found for query.
2025-09-19 10:56:48,958 [INFO] novinhub - No matching messages found for query.
2025-09-19 10:56:59,367 [INFO] novinhub - No matching messages found for query.
2025-09-19 10:57:09,780 [INFO] novinhub - No matching messages found for query.
2025-09-19 10:57:19,783 [ERROR] novinhub - Error in full workflow.
Traceback (most recent call last):
  File "D:\MyProject\SalamatSaleDepartment\MainWebSite\WWW\python\ImportPhone_Novinhub.py", line 505, in run_full_workflow
    while True:
              ^
  File "C:\Users\amira\AppData\Local\Programs\Python\Python313\Lib\asyncio\threads.py", line 25, in to_thread
    return await loop.run_in_executor(None, func_call)
                 ~~~~~~~~~~~~~~~~~~~~^^^^^^^^^^^^^^^^^
  File "C:\Users\amira\AppData\Local\Programs\Python\Python313\Lib\asyncio\base_events.py", line 901, in run_in_executor
    executor.submit(func, *args), loop=self)
    ~~~~~~~~~~~~~~~^^^^^^^^^^^^^
  File "C:\Users\amira\AppData\Local\Programs\Python\Python313\Lib\concurrent\futures\thread.py", line 171, in submit
    raise RuntimeError('cannot schedule new futures after shutdown')
RuntimeError: cannot schedule new futures after shutdown
2025-09-19 10:57:19,798 [INFO] novinhub - Async workflow finished successfully in background.
2025-09-19 10:57:38,612 [INFO] novinhub - Background workflow task scheduled successfully.
2025-09-19 10:57:38,617 [INFO] novinhub - Background task started. Running the async workflow.
2025-09-19 10:57:38,620 [INFO] novinhub - Running robot before checking email...
2025-09-19 10:57:38,621 [INFO] novinhub - Starting Selenium robot...
2025-09-19 10:57:41,866 [INFO] novinhub - Opened start URL: https://app.novinhub.com/login?redirect=%2Fdashboard
2025-09-19 10:58:18,241 [ERROR] novinhub - An error occurred during Selenium robot execution: HTTPConnectionPool(host='localhost', port=53556): Max retries exceeded with url: /session/66c6d342692ae1d07456bd0586f7e0fc/element (Caused by NewConnectionError('<urllib3.connection.HTTPConnection object at 0x000001D28E99BBB0>: Failed to establish a new connection: [WinError 10061] No connection could be made because the target machine actively refused it'))
Traceback (most recent call last):
  File "C:\Users\amira\AppData\Local\Programs\Python\Python313\Lib\site-packages\urllib3\connection.py", line 198, in _new_conn
    sock = connection.create_connection(
        (self._dns_host, self.port),
    ...<2 lines>...
        socket_options=self.socket_options,
    )
  File "C:\Users\amira\AppData\Local\Programs\Python\Python313\Lib\site-packages\urllib3\util\connection.py", line 85, in create_connection
    raise err
  File "C:\Users\amira\AppData\Local\Programs\Python\Python313\Lib\site-packages\urllib3\util\connection.py", line 73, in create_connection
    sock.connect(sa)
    ~~~~~~~~~~~~^^^^
ConnectionRefusedError: [WinError 10061] No connection could be made because the target machine actively refused it

The above exception was the direct cause of the following exception:

Traceback (most recent call last):
  File "C:\Users\amira\AppData\Local\Programs\Python\Python313\Lib\site-packages\urllib3\connectionpool.py", line 787, in urlopen
    response = self._make_request(
        conn,
    ...<10 lines>...
        **response_kw,
    )
  File "C:\Users\amira\AppData\Local\Programs\Python\Python313\Lib\site-packages\urllib3\connectionpool.py", line 493, in _make_request
    conn.request(
    ~~~~~~~~~~~~^
        method,
        ^^^^^^^
    ...<6 lines>...
        enforce_content_length=enforce_content_length,
        ^^^^^^^^^^^^^^^^^^^^^^^^^^^^^^^^^^^^^^^^^^^^^^
    )
    ^
  File "C:\Users\amira\AppData\Local\Programs\Python\Python313\Lib\site-packages\urllib3\connection.py", line 494, in request
    self.endheaders()
    ~~~~~~~~~~~~~~~^^
  File "C:\Users\amira\AppData\Local\Programs\Python\Python313\Lib\http\client.py", line 1333, in endheaders
    self._send_output(message_body, encode_chunked=encode_chunked)
    ~~~~~~~~~~~~~~~~~^^^^^^^^^^^^^^^^^^^^^^^^^^^^^^^^^^^^^^^^^^^^^
  File "C:\Users\amira\AppData\Local\Programs\Python\Python313\Lib\http\client.py", line 1093, in _send_output
    self.send(msg)
    ~~~~~~~~~^^^^^
  File "C:\Users\amira\AppData\Local\Programs\Python\Python313\Lib\http\client.py", line 1037, in send
    self.connect()
    ~~~~~~~~~~~~^^
  File "C:\Users\amira\AppData\Local\Programs\Python\Python313\Lib\site-packages\urllib3\connection.py", line 325, in connect
    self.sock = self._new_conn()
                ~~~~~~~~~~~~~~^^
  File "C:\Users\amira\AppData\Local\Programs\Python\Python313\Lib\site-packages\urllib3\connection.py", line 213, in _new_conn
    raise NewConnectionError(
        self, f"Failed to establish a new connection: {e}"
    ) from e
urllib3.exceptions.NewConnectionError: <urllib3.connection.HTTPConnection object at 0x000001D28E99BBB0>: Failed to establish a new connection: [WinError 10061] No connection could be made because the target machine actively refused it

The above exception was the direct cause of the following exception:

Traceback (most recent call last):
  File "D:\MyProject\SalamatSaleDepartment\MainWebSite\WWW\python\ImportPhone_Novinhub.py", line 386, in run_robot
    if not is_logged_in(driver, wait):
           ~~~~~~~~~~~~^^^^^^^^^^^^^^
  File "D:\MyProject\SalamatSaleDepartment\MainWebSite\WWW\python\ImportPhone_Novinhub.py", line 478, in is_logged_in
    short_wait.until(EC.presence_of_element_located((By.XPATH, profile_button_selector)))
    ~~~~~~~~~~~~~~~~^^^^^^^^^^^^^^^^^^^^^^^^^^^^^^^^^^^^^^^^^^^^^^^^^^^^^^^^^^^^^^^^^^^^^
  File "C:\Users\amira\AppData\Local\Programs\Python\Python313\Lib\site-packages\selenium\webdriver\support\wait.py", line 129, in until
    value = method(self._driver)
  File "C:\Users\amira\AppData\Local\Programs\Python\Python313\Lib\site-packages\selenium\webdriver\support\expected_conditions.py", line 104, in _predicate
    return driver.find_element(*locator)
           ~~~~~~~~~~~~~~~~~~~^^^^^^^^^^
  File "C:\Users\amira\AppData\Local\Programs\Python\Python313\Lib\site-packages\selenium\webdriver\remote\webdriver.py", line 926, in find_element
    return self.execute(Command.FIND_ELEMENT, {"using": by, "value": value})["value"]
           ~~~~~~~~~~~~^^^^^^^^^^^^^^^^^^^^^^^^^^^^^^^^^^^^^^^^^^^^^^^^^^^^^
  File "C:\Users\amira\AppData\Local\Programs\Python\Python313\Lib\site-packages\selenium\webdriver\remote\webdriver.py", line 455, in execute
    response = cast(RemoteConnection, self.command_executor).execute(driver_command, params)
  File "C:\Users\amira\AppData\Local\Programs\Python\Python313\Lib\site-packages\selenium\webdriver\remote\remote_connection.py", line 406, in execute
    return self._request(command_info[0], url, body=data)
           ~~~~~~~~~~~~~^^^^^^^^^^^^^^^^^^^^^^^^^^^^^^^^^
  File "C:\Users\amira\AppData\Local\Programs\Python\Python313\Lib\site-packages\selenium\webdriver\remote\remote_connection.py", line 430, in _request
    response = self._conn.request(method, url, body=body, headers=headers, timeout=self._client_config.timeout)
  File "C:\Users\amira\AppData\Local\Programs\Python\Python313\Lib\site-packages\urllib3\_request_methods.py", line 143, in request
    return self.request_encode_body(
           ~~~~~~~~~~~~~~~~~~~~~~~~^
        method, url, fields=fields, headers=headers, **urlopen_kw
        ^^^^^^^^^^^^^^^^^^^^^^^^^^^^^^^^^^^^^^^^^^^^^^^^^^^^^^^^^
    )
    ^
  File "C:\Users\amira\AppData\Local\Programs\Python\Python313\Lib\site-packages\urllib3\_request_methods.py", line 278, in request_encode_body
    return self.urlopen(method, url, **extra_kw)
           ~~~~~~~~~~~~^^^^^^^^^^^^^^^^^^^^^^^^^
  File "C:\Users\amira\AppData\Local\Programs\Python\Python313\Lib\site-packages\urllib3\poolmanager.py", line 459, in urlopen
    response = conn.urlopen(method, u.request_uri, **kw)
  File "C:\Users\amira\AppData\Local\Programs\Python\Python313\Lib\site-packages\urllib3\connectionpool.py", line 871, in urlopen
    return self.urlopen(
           ~~~~~~~~~~~~^
        method,
        ^^^^^^^
    ...<13 lines>...
        **response_kw,
        ^^^^^^^^^^^^^^
    )
    ^
  File "C:\Users\amira\AppData\Local\Programs\Python\Python313\Lib\site-packages\urllib3\connectionpool.py", line 871, in urlopen
    return self.urlopen(
           ~~~~~~~~~~~~^
        method,
        ^^^^^^^
    ...<13 lines>...
        **response_kw,
        ^^^^^^^^^^^^^^
    )
    ^
  File "C:\Users\amira\AppData\Local\Programs\Python\Python313\Lib\site-packages\urllib3\connectionpool.py", line 871, in urlopen
    return self.urlopen(
           ~~~~~~~~~~~~^
        method,
        ^^^^^^^
    ...<13 lines>...
        **response_kw,
        ^^^^^^^^^^^^^^
    )
    ^
  File "C:\Users\amira\AppData\Local\Programs\Python\Python313\Lib\site-packages\urllib3\connectionpool.py", line 841, in urlopen
    retries = retries.increment(
        method, url, error=new_e, _pool=self, _stacktrace=sys.exc_info()[2]
    )
  File "C:\Users\amira\AppData\Local\Programs\Python\Python313\Lib\site-packages\urllib3\util\retry.py", line 519, in increment
    raise MaxRetryError(_pool, url, reason) from reason  # type: ignore[arg-type]
    ^^^^^^^^^^^^^^^^^^^^^^^^^^^^^^^^^^^^^^^^^^^^^^^^^^^
urllib3.exceptions.MaxRetryError: HTTPConnectionPool(host='localhost', port=53556): Max retries exceeded with url: /session/66c6d342692ae1d07456bd0586f7e0fc/element (Caused by NewConnectionError('<urllib3.connection.HTTPConnection object at 0x000001D28E99BBB0>: Failed to establish a new connection: [WinError 10061] No connection could be made because the target machine actively refused it'))
2025-09-19 10:59:04,716 [INFO] novinhub - Selenium robot finished.
2025-09-19 10:59:04,717 [ERROR] novinhub - Error in full workflow.
Traceback (most recent call last):
  File "D:\MyProject\SalamatSaleDepartment\MainWebSite\WWW\python\ImportPhone_Novinhub.py", line 501, in run_full_workflow
    service = await asyncio.to_thread(get_gmail_service)
              ^^^^^^^^^^^^^^^^^^^^^^^^^^^^^^^^^^^^^^^^^^
  File "C:\Users\amira\AppData\Local\Programs\Python\Python313\Lib\asyncio\threads.py", line 25, in to_thread
    return await loop.run_in_executor(None, func_call)
                 ~~~~~~~~~~~~~~~~~~~~^^^^^^^^^^^^^^^^^
  File "C:\Users\amira\AppData\Local\Programs\Python\Python313\Lib\asyncio\base_events.py", line 901, in run_in_executor
    executor.submit(func, *args), loop=self)
    ~~~~~~~~~~~~~~~^^^^^^^^^^^^^
  File "C:\Users\amira\AppData\Local\Programs\Python\Python313\Lib\concurrent\futures\thread.py", line 171, in submit
    raise RuntimeError('cannot schedule new futures after shutdown')
RuntimeError: cannot schedule new futures after shutdown
2025-09-19 10:59:04,721 [INFO] novinhub - Async workflow finished successfully in background.
2025-09-19 10:59:20,487 [INFO] novinhub - Background workflow task scheduled successfully.
2025-09-19 10:59:20,493 [INFO] novinhub - Background task started. Running the async workflow.
2025-09-19 10:59:20,495 [INFO] novinhub - Running robot before checking email...
2025-09-19 10:59:20,496 [INFO] novinhub - Starting Selenium robot...
2025-09-19 10:59:27,384 [INFO] novinhub - Opened start URL: https://app.novinhub.com/login?redirect=%2Fdashboard
2025-09-19 10:59:52,484 [ERROR] novinhub - An error occurred during Selenium robot execution: Message: 
Stacktrace:
	GetHandleVerifier [0x0x430c13+66051]
	GetHandleVerifier [0x0x430c54+66116]
	(No symbol) [0x0x20db33]
	(No symbol) [0x0x2578a8]
	(No symbol) [0x0x257c4b]
	(No symbol) [0x0x29e0a2]
	(No symbol) [0x0x279fd4]
	(No symbol) [0x0x29b7f1]
	(No symbol) [0x0x279d86]
	(No symbol) [0x0x24b53e]
	(No symbol) [0x0x24c414]
	GetHandleVerifier [0x0x678a13+2457603]
	GetHandleVerifier [0x0x6739d2+2437058]
	GetHandleVerifier [0x0x4597f2+232930]
	GetHandleVerifier [0x0x449a18+167944]
	GetHandleVerifier [0x0x45092d+196381]
	GetHandleVerifier [0x0x438ee8+99544]
	GetHandleVerifier [0x0x439082+99954]
	GetHandleVerifier [0x0x42322a+10266]
	BaseThreadInitThunk [0x0x76395d49+25]
	RtlInitializeExceptionChain [0x0x775ad6db+107]
	RtlGetAppContainerNamedObjectPath [0x0x775ad661+561]
Traceback (most recent call last):
  File "D:\MyProject\SalamatSaleDepartment\MainWebSite\WWW\python\ImportPhone_Novinhub.py", line 386, in run_robot
    if not is_logged_in(driver, wait):
           ~~~~~~~~~~~~^^^^^^^^^^^^^^
  File "D:\MyProject\SalamatSaleDepartment\MainWebSite\WWW\python\ImportPhone_Novinhub.py", line 478, in is_logged_in
    short_wait.until(EC.presence_of_element_located((By.XPATH, profile_button_selector)))
    ~~~~~~~~~~~~~~~~^^^^^^^^^^^^^^^^^^^^^^^^^^^^^^^^^^^^^^^^^^^^^^^^^^^^^^^^^^^^^^^^^^^^^
  File "C:\Users\amira\AppData\Local\Programs\Python\Python313\Lib\site-packages\selenium\webdriver\support\wait.py", line 138, in until
    raise TimeoutException(message, screen, stacktrace)
selenium.common.exceptions.TimeoutException: Message: 
Stacktrace:
	GetHandleVerifier [0x0x430c13+66051]
	GetHandleVerifier [0x0x430c54+66116]
	(No symbol) [0x0x20db33]
	(No symbol) [0x0x2578a8]
	(No symbol) [0x0x257c4b]
	(No symbol) [0x0x29e0a2]
	(No symbol) [0x0x279fd4]
	(No symbol) [0x0x29b7f1]
	(No symbol) [0x0x279d86]
	(No symbol) [0x0x24b53e]
	(No symbol) [0x0x24c414]
	GetHandleVerifier [0x0x678a13+2457603]
	GetHandleVerifier [0x0x6739d2+2437058]
	GetHandleVerifier [0x0x4597f2+232930]
	GetHandleVerifier [0x0x449a18+167944]
	GetHandleVerifier [0x0x45092d+196381]
	GetHandleVerifier [0x0x438ee8+99544]
	GetHandleVerifier [0x0x439082+99954]
	GetHandleVerifier [0x0x42322a+10266]
	BaseThreadInitThunk [0x0x76395d49+25]
	RtlInitializeExceptionChain [0x0x775ad6db+107]
	RtlGetAppContainerNamedObjectPath [0x0x775ad661+561]

2025-09-19 11:00:24,641 [INFO] novinhub - Selenium robot finished.
2025-09-19 11:00:24,642 [INFO] novinhub - Authenticating Gmail API...
2025-09-19 11:00:24,647 [INFO] novinhub - Gmail service ready.
2025-09-19 11:00:24,647 [INFO] novinhub - Polling for report email for up to 180 seconds...
2025-09-19 11:00:25,648 [INFO] novinhub - No matching messages found for query.
2025-09-19 11:00:28,062 [INFO] novinhub - Background workflow task scheduled successfully.
2025-09-19 11:00:28,064 [INFO] novinhub - Background task started. Running the async workflow.
2025-09-19 11:00:28,065 [INFO] novinhub - Running robot before checking email...
2025-09-19 11:00:28,065 [INFO] novinhub - Starting Selenium robot...
2025-09-19 11:00:31,223 [INFO] novinhub - Opened start URL: https://app.novinhub.com/login?redirect=%2Fdashboard
2025-09-19 11:00:36,056 [INFO] novinhub - No matching messages found for query.
2025-09-19 11:00:47,425 [INFO] novinhub - No matching messages found for query.
2025-09-19 11:00:57,845 [INFO] novinhub - No matching messages found for query.
2025-09-19 11:01:18,474 [INFO] novinhub - Background workflow task scheduled successfully.
2025-09-19 11:01:18,480 [INFO] novinhub - Background task started. Running the async workflow.
2025-09-19 11:01:18,481 [INFO] novinhub - Running robot before checking email...
2025-09-19 11:01:18,483 [INFO] novinhub - Starting Selenium robot...
2025-09-19 11:01:21,743 [INFO] novinhub - Opened start URL: https://app.novinhub.com/login?redirect=%2Fdashboard
2025-09-19 11:01:26,841 [ERROR] novinhub - An error occurred during Selenium robot execution: Message: 
Stacktrace:
	GetHandleVerifier [0x0x430c13+66051]
	GetHandleVerifier [0x0x430c54+66116]
	(No symbol) [0x0x20db33]
	(No symbol) [0x0x2578a8]
	(No symbol) [0x0x257c4b]
	(No symbol) [0x0x29e0a2]
	(No symbol) [0x0x279fd4]
	(No symbol) [0x0x29b7f1]
	(No symbol) [0x0x279d86]
	(No symbol) [0x0x24b53e]
	(No symbol) [0x0x24c414]
	GetHandleVerifier [0x0x678a13+2457603]
	GetHandleVerifier [0x0x6739d2+2437058]
	GetHandleVerifier [0x0x4597f2+232930]
	GetHandleVerifier [0x0x449a18+167944]
	GetHandleVerifier [0x0x45092d+196381]
	GetHandleVerifier [0x0x438ee8+99544]
	GetHandleVerifier [0x0x439082+99954]
	GetHandleVerifier [0x0x42322a+10266]
	BaseThreadInitThunk [0x0x76395d49+25]
	RtlInitializeExceptionChain [0x0x775ad6db+107]
	RtlGetAppContainerNamedObjectPath [0x0x775ad661+561]
Traceback (most recent call last):
  File "D:\MyProject\SalamatSaleDepartment\MainWebSite\WWW\python\ImportPhone_Novinhub.py", line 385, in run_robot
    if not is_logged_in(driver, wait):
           ~~~~~~~~~~~~^^^^^^^^^^^^^^
  File "D:\MyProject\SalamatSaleDepartment\MainWebSite\WWW\python\ImportPhone_Novinhub.py", line 477, in is_logged_in
    short_wait.until(EC.presence_of_element_located((By.XPATH, profile_button_selector)))
    ~~~~~~~~~~~~~~~~^^^^^^^^^^^^^^^^^^^^^^^^^^^^^^^^^^^^^^^^^^^^^^^^^^^^^^^^^^^^^^^^^^^^^
  File "C:\Users\amira\AppData\Local\Programs\Python\Python313\Lib\site-packages\selenium\webdriver\support\wait.py", line 138, in until
    raise TimeoutException(message, screen, stacktrace)
selenium.common.exceptions.TimeoutException: Message: 
Stacktrace:
	GetHandleVerifier [0x0x430c13+66051]
	GetHandleVerifier [0x0x430c54+66116]
	(No symbol) [0x0x20db33]
	(No symbol) [0x0x2578a8]
	(No symbol) [0x0x257c4b]
	(No symbol) [0x0x29e0a2]
	(No symbol) [0x0x279fd4]
	(No symbol) [0x0x29b7f1]
	(No symbol) [0x0x279d86]
	(No symbol) [0x0x24b53e]
	(No symbol) [0x0x24c414]
	GetHandleVerifier [0x0x678a13+2457603]
	GetHandleVerifier [0x0x6739d2+2437058]
	GetHandleVerifier [0x0x4597f2+232930]
	GetHandleVerifier [0x0x449a18+167944]
	GetHandleVerifier [0x0x45092d+196381]
	GetHandleVerifier [0x0x438ee8+99544]
	GetHandleVerifier [0x0x439082+99954]
	GetHandleVerifier [0x0x42322a+10266]
	BaseThreadInitThunk [0x0x76395d49+25]
	RtlInitializeExceptionChain [0x0x775ad6db+107]
	RtlGetAppContainerNamedObjectPath [0x0x775ad661+561]

2025-09-19 11:01:58,999 [INFO] novinhub - Selenium robot finished.
2025-09-19 11:01:59,000 [INFO] novinhub - Authenticating Gmail API...
2025-09-19 11:01:59,777 [INFO] novinhub - Gmail service ready.
2025-09-19 11:01:59,777 [INFO] novinhub - Polling for report email for up to 180 seconds...
2025-09-19 11:02:00,733 [INFO] novinhub - No matching messages found for query.
2025-09-19 11:02:11,148 [INFO] novinhub - No matching messages found for query.
2025-09-19 11:02:21,572 [INFO] novinhub - No matching messages found for query.
2025-09-19 11:02:31,985 [INFO] novinhub - No matching messages found for query.
2025-09-19 11:02:42,396 [INFO] novinhub - No matching messages found for query.
2025-09-19 11:02:52,802 [INFO] novinhub - No matching messages found for query.
2025-09-19 11:03:02,816 [ERROR] novinhub - Error in full workflow.
Traceback (most recent call last):
  File "D:\MyProject\SalamatSaleDepartment\MainWebSite\WWW\python\ImportPhone_Novinhub.py", line 505, in run_full_workflow
    msg = await asyncio.to_thread(find_recent_email, service)
          ^^^^^^^^^^^^^^^^^^^^^^^^^^^^^^^^^^^^^^^^^^^^^^^^^^^
  File "C:\Users\amira\AppData\Local\Programs\Python\Python313\Lib\asyncio\threads.py", line 25, in to_thread
    return await loop.run_in_executor(None, func_call)
                 ~~~~~~~~~~~~~~~~~~~~^^^^^^^^^^^^^^^^^
  File "C:\Users\amira\AppData\Local\Programs\Python\Python313\Lib\asyncio\base_events.py", line 901, in run_in_executor
    executor.submit(func, *args), loop=self)
    ~~~~~~~~~~~~~~~^^^^^^^^^^^^^
  File "C:\Users\amira\AppData\Local\Programs\Python\Python313\Lib\concurrent\futures\thread.py", line 171, in submit
    raise RuntimeError('cannot schedule new futures after shutdown')
RuntimeError: cannot schedule new futures after shutdown
2025-09-19 11:03:02,820 [INFO] novinhub - Async workflow finished successfully in background.
2025-09-19 11:03:04,317 [INFO] novinhub - Background workflow task scheduled successfully.
2025-09-19 11:03:04,321 [INFO] novinhub - Background task started. Running the async workflow.
2025-09-19 11:03:04,323 [INFO] novinhub - Running robot before checking email...
2025-09-19 11:03:04,324 [INFO] novinhub - Starting Selenium robot...
2025-09-19 11:03:07,618 [INFO] novinhub - Opened start URL: https://app.novinhub.com/login?redirect=%2Fdashboard
2025-09-19 11:03:12,729 [INFO] novinhub - User is not logged in. Proceeding with login steps.
2025-09-19 11:03:12,729 [INFO] novinhub - Attempting to log in...
2025-09-19 11:03:16,430 [INFO] novinhub - Login form submitted. Waiting for dashboard or CAPTCHA...
2025-09-19 11:03:18,978 [INFO] novinhub - Login successful, dashboard loaded.
2025-09-19 11:03:18,979 [INFO] novinhub - Navigating to automation page...
2025-09-19 11:03:19,420 [INFO] novinhub - Navigating to export numbers tab...
2025-09-19 11:03:22,371 [INFO] novinhub - Clicking 'Export' button...
2025-09-19 11:03:22,456 [INFO] novinhub - Filling out the export modal form...
2025-09-19 11:03:22,624 [INFO] novinhub - Submitting the export request...
2025-09-19 11:03:22,684 [INFO] novinhub - Selenium robot has successfully requested the Excel file.
2025-09-19 11:03:24,849 [INFO] novinhub - Selenium robot finished.
2025-09-19 11:03:24,850 [INFO] novinhub - Authenticating Gmail API...
2025-09-19 11:03:24,863 [INFO] novinhub - Gmail service ready.
2025-09-19 11:03:24,863 [INFO] novinhub - Polling for report email for up to 180 seconds...
2025-09-19 11:03:25,907 [INFO] novinhub - No matching messages found for query.
2025-09-19 11:03:36,332 [INFO] novinhub - No matching messages found for query.
2025-09-19 11:03:46,768 [INFO] novinhub - No matching messages found for query.
2025-09-19 11:03:57,197 [INFO] novinhub - No matching messages found for query.
2025-09-19 11:04:07,637 [INFO] novinhub - No matching messages found for query.
2025-09-19 11:04:18,060 [INFO] novinhub - No matching messages found for query.
2025-09-19 11:04:28,488 [INFO] novinhub - No matching messages found for query.
2025-09-19 11:04:38,496 [ERROR] novinhub - Error in full workflow.
Traceback (most recent call last):
  File "D:\MyProject\SalamatSaleDepartment\MainWebSite\WWW\python\ImportPhone_Novinhub.py", line 505, in run_full_workflow
    service = await asyncio.to_thread(get_gmail_service)
              ^^^^^^^^^^^^^^^^^^^^^^^^^^^^^^^^^^^^^^^^^^
  File "C:\Users\amira\AppData\Local\Programs\Python\Python313\Lib\asyncio\threads.py", line 25, in to_thread
    return await loop.run_in_executor(None, func_call)
                 ~~~~~~~~~~~~~~~~~~~~^^^^^^^^^^^^^^^^^
  File "C:\Users\amira\AppData\Local\Programs\Python\Python313\Lib\asyncio\base_events.py", line 901, in run_in_executor
    executor.submit(func, *args), loop=self)
    ~~~~~~~~~~~~~~~^^^^^^^^^^^^^
  File "C:\Users\amira\AppData\Local\Programs\Python\Python313\Lib\concurrent\futures\thread.py", line 171, in submit
    raise RuntimeError('cannot schedule new futures after shutdown')
RuntimeError: cannot schedule new futures after shutdown
2025-09-19 11:04:38,500 [INFO] novinhub - Async workflow finished successfully in background.
2025-09-19 11:05:01,961 [INFO] novinhub - Background workflow task scheduled successfully.
2025-09-19 11:05:01,967 [INFO] novinhub - Background task started. Running the async workflow.
2025-09-19 11:05:01,969 [INFO] novinhub - Running robot before checking email...
2025-09-19 11:05:01,970 [INFO] novinhub - Starting Selenium robot...
2025-09-19 11:05:05,315 [INFO] novinhub - Opened start URL: https://app.novinhub.com/login?redirect=%2Fdashboard
2025-09-19 11:05:06,852 [INFO] novinhub - User is already logged in.
2025-09-19 11:05:06,853 [INFO] novinhub - Navigating to automation page...
2025-09-19 11:05:08,424 [INFO] novinhub - Navigating to export numbers tab...
2025-09-19 11:05:12,144 [INFO] novinhub - Clicking 'Export' button...
2025-09-19 11:05:12,847 [INFO] novinhub - Filling out the export modal form...
2025-09-19 11:05:14,210 [INFO] novinhub - Submitting the export request...
2025-09-19 11:05:14,781 [INFO] novinhub - Selenium robot has successfully requested the Excel file.
2025-09-19 11:05:16,961 [INFO] novinhub - Selenium robot finished.
2025-09-19 11:05:16,962 [INFO] novinhub - Authenticating Gmail API...
2025-09-19 11:05:16,966 [INFO] novinhub - Gmail service ready.
2025-09-19 11:05:16,966 [INFO] novinhub - Polling for report email for up to 180 seconds...
2025-09-19 11:05:17,935 [INFO] novinhub - No matching messages found for query.
2025-09-19 11:05:28,337 [INFO] novinhub - No matching messages found for query.
2025-09-19 11:05:38,761 [INFO] novinhub - No matching messages found for query.
2025-09-19 11:05:42,066 [INFO] novinhub - Background workflow task scheduled successfully.
2025-09-19 11:05:42,067 [INFO] novinhub - Background task started. Running the async workflow.
2025-09-19 11:05:42,069 [INFO] novinhub - Running robot before checking email...
2025-09-19 11:05:42,069 [INFO] novinhub - Starting Selenium robot...
2025-09-19 11:05:45,224 [INFO] novinhub - Opened start URL: https://app.novinhub.com/login?redirect=%2Fdashboard
2025-09-19 11:05:46,777 [INFO] novinhub - User is already logged in.
2025-09-19 11:05:46,777 [INFO] novinhub - Navigating to automation page...
2025-09-19 11:05:48,114 [INFO] novinhub - Navigating to export numbers tab...
2025-09-19 11:05:49,251 [INFO] novinhub - No matching messages found for query.
2025-09-19 11:05:51,561 [INFO] novinhub - Clicking 'Export' button...
2025-09-19 11:05:52,495 [INFO] novinhub - Filling out the export modal form...
2025-09-19 11:05:53,932 [INFO] novinhub - Submitting the export request...
2025-09-19 11:05:54,782 [INFO] novinhub - Selenium robot has successfully requested the Excel file.
2025-09-19 11:05:56,798 [INFO] novinhub - Selenium robot finished.
2025-09-19 11:05:56,799 [INFO] novinhub - Authenticating Gmail API...
2025-09-19 11:05:56,802 [INFO] novinhub - Gmail service ready.
2025-09-19 11:05:56,803 [INFO] novinhub - Polling for report email for up to 180 seconds...
2025-09-19 11:05:57,875 [INFO] novinhub - No matching messages found for query.
2025-09-19 11:05:59,625 [INFO] novinhub - No matching messages found for query.
2025-09-19 11:07:57,125 [INFO] novinhub - Background workflow task scheduled successfully.
2025-09-19 11:07:57,131 [INFO] novinhub - Background task started. Running the async workflow.
2025-09-19 11:07:57,133 [INFO] novinhub - Running robot before checking email...
2025-09-19 11:07:57,135 [INFO] novinhub - Starting Selenium robot...
2025-09-19 11:08:00,685 [INFO] novinhub - Opened start URL: https://app.novinhub.com/login?redirect=%2Fdashboard
2025-09-19 11:08:02,220 [INFO] novinhub - User is already logged in.
2025-09-19 11:08:02,221 [INFO] novinhub - Navigating to automation page...
2025-09-19 11:08:04,136 [INFO] novinhub - Navigating to export numbers tab...
2025-09-19 11:08:07,500 [INFO] novinhub - Clicking 'Export' button...
2025-09-19 11:08:08,326 [INFO] novinhub - Filling out the export modal form...
2025-09-19 11:08:09,700 [INFO] novinhub - Submitting the export request...
2025-09-19 11:08:10,341 [INFO] novinhub - Selenium robot has successfully requested the Excel file.
2025-09-19 11:08:12,528 [INFO] novinhub - Selenium robot finished.
2025-09-19 11:08:12,529 [INFO] novinhub - Authenticating Gmail API...
2025-09-19 11:08:12,533 [INFO] novinhub - Gmail service ready.
2025-09-19 11:08:12,533 [INFO] novinhub - Polling for report email for up to 180 seconds...
2025-09-19 11:08:13,742 [INFO] novinhub - No matching messages found for query.
2025-09-19 11:08:24,151 [INFO] novinhub - No matching messages found for query.
2025-09-19 11:08:34,586 [INFO] novinhub - No matching messages found for query.
2025-09-19 11:08:45,002 [INFO] novinhub - No matching messages found for query.
2025-09-19 11:08:55,498 [INFO] novinhub - No matching messages found for query.
2025-09-19 11:09:05,942 [INFO] novinhub - No matching messages found for query.
2025-09-19 11:09:16,372 [INFO] novinhub - No matching messages found for query.
2025-09-19 11:09:26,815 [INFO] novinhub - No matching messages found for query.
2025-09-19 11:09:37,331 [INFO] novinhub - No matching messages found for query.
2025-09-19 11:09:47,747 [INFO] novinhub - No matching messages found for query.
2025-09-19 11:09:58,165 [INFO] novinhub - No matching messages found for query.
2025-09-19 11:10:09,060 [INFO] novinhub - No matching messages found for query.
2025-09-19 11:10:19,468 [INFO] novinhub - No matching messages found for query.
2025-09-19 11:10:29,868 [INFO] novinhub - No matching messages found for query.
2025-09-19 11:10:40,276 [INFO] novinhub - No matching messages found for query.
2025-09-19 11:10:50,684 [INFO] novinhub - No matching messages found for query.
2025-09-19 11:11:01,088 [INFO] novinhub - No matching messages found for query.
2025-09-19 11:11:11,505 [INFO] novinhub - No matching messages found for query.
2025-09-19 11:11:21,914 [INFO] novinhub - No matching messages found for query.
2025-09-19 11:11:21,915 [WARNING] novinhub - Timeout while waiting for report email.
2025-09-19 11:11:21,917 [INFO] novinhub - Async workflow finished successfully in background.
2025-09-19 23:28:38,351 [INFO] novinhub - Goftino sync process has been scheduled in the background.
2025-09-19 23:28:38,410 [ERROR] novinhub - An error occurred during Goftino sync: 2017 (HY000): Can't open named pipe to host: .  pipe: MySQL (2)
Traceback (most recent call last):
  File "C:\Users\amira\AppData\Local\Programs\Python\Python313\Lib\site-packages\mysql\connector\connection_cext.py", line 354, in _open_connection
    self._cmysql.connect(**cnx_kwargs)
    ~~~~~~~~~~~~~~~~~~~~^^^^^^^^^^^^^^
_mysql_connector.MySQLInterfaceError: Can't open named pipe to host: .  pipe: MySQL (2)

The above exception was the direct cause of the following exception:

Traceback (most recent call last):
  File "D:\MyProject\SalamatSaleDepartment\MainWebSite\WWW\python\ImportPhone_Novinhub.py", line 614, in sync_goftino_chats
    db_connection = mysql.connector.connect(host=DB_HOST, database=DB_DATABASE, user=DB_USER, password=DB_PASS)
  File "C:\Users\amira\AppData\Local\Programs\Python\Python313\Lib\site-packages\mysql\connector\pooling.py", line 322, in connect
    return CMySQLConnection(*args, **kwargs)
  File "C:\Users\amira\AppData\Local\Programs\Python\Python313\Lib\site-packages\mysql\connector\connection_cext.py", line 142, in __init__
    self.connect(**kwargs)
    ~~~~~~~~~~~~^^^^^^^^^^
  File "C:\Users\amira\AppData\Local\Programs\Python\Python313\Lib\site-packages\mysql\connector\abstracts.py", line 1604, in connect
    self._open_connection()
    ~~~~~~~~~~~~~~~~~~~~~^^
  File "C:\Users\amira\AppData\Local\Programs\Python\Python313\Lib\site-packages\mysql\connector\connection_cext.py", line 360, in _open_connection
    raise get_mysql_exception(
        err.errno, msg=err.msg, sqlstate=err.sqlstate
    ) from err
mysql.connector.errors.DatabaseError: 2017 (HY000): Can't open named pipe to host: .  pipe: MySQL (2)
2025-09-19 23:29:37,584 [INFO] novinhub - Goftino sync process has been scheduled in the background.
2025-09-19 23:29:37,585 [ERROR] novinhub - An error occurred during Goftino sync: 2017 (HY000): Can't open named pipe to host: .  pipe: MySQL (2)
Traceback (most recent call last):
  File "C:\Users\amira\AppData\Local\Programs\Python\Python313\Lib\site-packages\mysql\connector\connection_cext.py", line 354, in _open_connection
    self._cmysql.connect(**cnx_kwargs)
    ~~~~~~~~~~~~~~~~~~~~^^^^^^^^^^^^^^
_mysql_connector.MySQLInterfaceError: Can't open named pipe to host: .  pipe: MySQL (2)

The above exception was the direct cause of the following exception:

Traceback (most recent call last):
  File "D:\MyProject\SalamatSaleDepartment\MainWebSite\WWW\python\ImportPhone_Novinhub.py", line 614, in sync_goftino_chats
    db_connection = mysql.connector.connect(host=DB_HOST, database=DB_DATABASE, user=DB_USER, password=DB_PASS)
  File "C:\Users\amira\AppData\Local\Programs\Python\Python313\Lib\site-packages\mysql\connector\pooling.py", line 322, in connect
    return CMySQLConnection(*args, **kwargs)
  File "C:\Users\amira\AppData\Local\Programs\Python\Python313\Lib\site-packages\mysql\connector\connection_cext.py", line 142, in __init__
    self.connect(**kwargs)
    ~~~~~~~~~~~~^^^^^^^^^^
  File "C:\Users\amira\AppData\Local\Programs\Python\Python313\Lib\site-packages\mysql\connector\abstracts.py", line 1604, in connect
    self._open_connection()
    ~~~~~~~~~~~~~~~~~~~~~^^
  File "C:\Users\amira\AppData\Local\Programs\Python\Python313\Lib\site-packages\mysql\connector\connection_cext.py", line 360, in _open_connection
    raise get_mysql_exception(
        err.errno, msg=err.msg, sqlstate=err.sqlstate
    ) from err
mysql.connector.errors.DatabaseError: 2017 (HY000): Can't open named pipe to host: .  pipe: MySQL (2)
2025-09-19 23:29:46,196 [INFO] novinhub - Goftino sync process has been scheduled in the background.
2025-09-19 23:29:46,205 [ERROR] novinhub - An error occurred during Goftino sync: 2017 (HY000): Can't open named pipe to host: .  pipe: MySQL (2)
Traceback (most recent call last):
  File "C:\Users\amira\AppData\Local\Programs\Python\Python313\Lib\site-packages\mysql\connector\connection_cext.py", line 354, in _open_connection
    self._cmysql.connect(**cnx_kwargs)
    ~~~~~~~~~~~~~~~~~~~~^^^^^^^^^^^^^^
_mysql_connector.MySQLInterfaceError: Can't open named pipe to host: .  pipe: MySQL (2)

The above exception was the direct cause of the following exception:

Traceback (most recent call last):
  File "D:\MyProject\SalamatSaleDepartment\MainWebSite\WWW\python\ImportPhone_Novinhub.py", line 614, in sync_goftino_chats
    db_connection = mysql.connector.connect(host=DB_HOST, database=DB_DATABASE, user=DB_USER, password=DB_PASS)
  File "C:\Users\amira\AppData\Local\Programs\Python\Python313\Lib\site-packages\mysql\connector\pooling.py", line 322, in connect
    return CMySQLConnection(*args, **kwargs)
  File "C:\Users\amira\AppData\Local\Programs\Python\Python313\Lib\site-packages\mysql\connector\connection_cext.py", line 142, in __init__
    self.connect(**kwargs)
    ~~~~~~~~~~~~^^^^^^^^^^
  File "C:\Users\amira\AppData\Local\Programs\Python\Python313\Lib\site-packages\mysql\connector\abstracts.py", line 1604, in connect
    self._open_connection()
    ~~~~~~~~~~~~~~~~~~~~~^^
  File "C:\Users\amira\AppData\Local\Programs\Python\Python313\Lib\site-packages\mysql\connector\connection_cext.py", line 360, in _open_connection
    raise get_mysql_exception(
        err.errno, msg=err.msg, sqlstate=err.sqlstate
    ) from err
mysql.connector.errors.DatabaseError: 2017 (HY000): Can't open named pipe to host: .  pipe: MySQL (2)
2025-09-19 23:30:24,383 [INFO] novinhub - Goftino sync process has been scheduled in the background.
2025-09-19 23:30:24,384 [ERROR] novinhub - An error occurred during Goftino sync: 2017 (HY000): Can't open named pipe to host: .  pipe: MySQL (2)
Traceback (most recent call last):
  File "C:\Users\amira\AppData\Local\Programs\Python\Python313\Lib\site-packages\mysql\connector\connection_cext.py", line 354, in _open_connection
    self._cmysql.connect(**cnx_kwargs)
    ~~~~~~~~~~~~~~~~~~~~^^^^^^^^^^^^^^
_mysql_connector.MySQLInterfaceError: Can't open named pipe to host: .  pipe: MySQL (2)

The above exception was the direct cause of the following exception:

Traceback (most recent call last):
  File "D:\MyProject\SalamatSaleDepartment\MainWebSite\WWW\python\ImportPhone_Novinhub.py", line 614, in sync_goftino_chats
    db_connection = mysql.connector.connect(host=DB_HOST, database=DB_DATABASE, user=DB_USER, password=DB_PASS)
  File "C:\Users\amira\AppData\Local\Programs\Python\Python313\Lib\site-packages\mysql\connector\pooling.py", line 322, in connect
    return CMySQLConnection(*args, **kwargs)
  File "C:\Users\amira\AppData\Local\Programs\Python\Python313\Lib\site-packages\mysql\connector\connection_cext.py", line 142, in __init__
    self.connect(**kwargs)
    ~~~~~~~~~~~~^^^^^^^^^^
  File "C:\Users\amira\AppData\Local\Programs\Python\Python313\Lib\site-packages\mysql\connector\abstracts.py", line 1604, in connect
    self._open_connection()
    ~~~~~~~~~~~~~~~~~~~~~^^
  File "C:\Users\amira\AppData\Local\Programs\Python\Python313\Lib\site-packages\mysql\connector\connection_cext.py", line 360, in _open_connection
    raise get_mysql_exception(
        err.errno, msg=err.msg, sqlstate=err.sqlstate
    ) from err
mysql.connector.errors.DatabaseError: 2017 (HY000): Can't open named pipe to host: .  pipe: MySQL (2)
2025-09-19 23:30:29,928 [INFO] novinhub - Goftino sync process has been scheduled in the background.
2025-09-19 23:30:29,971 [INFO] novinhub - Successfully connected to the MySQL database for Goftino sync.
2025-09-19 23:30:32,374 [ERROR] novinhub - Error fetching Goftino conversations: 401 Client Error: Unauthorized for url: https://api.goftino.com/v1/conversations?page=0&per_page=50
2025-09-19 23:30:32,374 [INFO] novinhub - No more conversations to fetch from Goftino.
2025-09-19 23:30:32,375 [INFO] novinhub - Sync complete. New Conversations: 0, New Messages: 0, New Phones Assigned: 0.
2025-09-19 23:30:32,378 [INFO] novinhub - Database connection for Goftino sync closed.
2025-09-19 23:32:38,314 [INFO] novinhub - Goftino sync process has been scheduled in the background.
2025-09-19 23:32:38,335 [INFO] novinhub - Successfully connected to the MySQL database for Goftino sync.
2025-09-19 23:32:44,061 [ERROR] novinhub - Error fetching Goftino conversations: 401 Client Error: Unauthorized for url: https://api.goftino.com/v1/conversations?page=0&per_page=50
2025-09-19 23:32:44,061 [INFO] novinhub - No more conversations to fetch from Goftino.
2025-09-19 23:32:44,062 [INFO] novinhub - Sync complete. New Conversations: 0, New Messages: 0, New Phones Assigned: 0.
2025-09-19 23:32:44,062 [INFO] novinhub - Database connection for Goftino sync closed.
2025-09-19 23:37:31,925 [INFO] novinhub - Goftino sync process has been scheduled in the background.
2025-09-19 23:37:31,945 [INFO] novinhub - Successfully connected to the MySQL database for Goftino sync.
2025-09-19 23:37:33,776 [ERROR] novinhub - Error fetching Goftino conversations: 400 Client Error: Bad Request for url: https://api.goftino.com/v1/conversations?page=0&per_page=50
2025-09-19 23:37:33,777 [INFO] novinhub - No more conversations to fetch from Goftino.
2025-09-19 23:37:33,777 [INFO] novinhub - Sync complete. New Conversations: 0, New Messages: 0, New Phones Assigned: 0.
2025-09-19 23:37:33,777 [INFO] novinhub - Database connection for Goftino sync closed.
2025-09-19 23:40:14,094 [INFO] novinhub - Goftino sync process has been scheduled in the background.
2025-09-19 23:40:14,123 [INFO] novinhub - Successfully connected to the MySQL database for Goftino sync.
2025-09-19 23:40:14,128 [INFO] novinhub - Fetching Goftino conversations page 0...
2025-09-19 23:40:16,051 [ERROR] novinhub - Error fetching Goftino conversations: 401 Client Error: Unauthorized for url: https://api.goftino.com/v1/conversations?apikey=dy2hfmkp1mhb27ieb1o8fayid3c5242fccbf08ee2d4a850244adacba400aac27&page=0&per_page=50
2025-09-19 23:40:16,051 [INFO] novinhub - No more conversations to fetch from Goftino.
2025-09-19 23:40:16,051 [INFO] novinhub - Sync complete. New Conversations: 0, New Messages: 0, New Phones Assigned: 0.
2025-09-19 23:40:16,052 [INFO] novinhub - Database connection for Goftino sync closed.
2025-09-19 23:40:54,190 [INFO] novinhub - Goftino sync process has been scheduled in the background.
2025-09-19 23:40:54,209 [INFO] novinhub - Successfully connected to the MySQL database for Goftino sync.
2025-09-19 23:40:56,257 [ERROR] novinhub - Error fetching Goftino conversations: 400 Client Error: Bad Request for url: https://api.goftino.com/v1/conversations?page=0&per_page=50
2025-09-19 23:40:56,257 [INFO] novinhub - No more conversations to fetch from Goftino.
2025-09-19 23:40:56,258 [INFO] novinhub - Sync complete. New Conversations: 0, New Messages: 0, New Phones Assigned: 0.
2025-09-19 23:40:56,258 [INFO] novinhub - Database connection for Goftino sync closed.
2025-09-19 23:44:06,777 [INFO] novinhub - Goftino sync process has been scheduled in the background.
2025-09-19 23:44:06,800 [INFO] novinhub - Successfully connected to the MySQL database for Goftino sync.
2025-09-19 23:44:08,823 [ERROR] novinhub - Error fetching Goftino conversations: 401 Client Error: Unauthorized for url: https://api.goftino.com/v1/conversations?page=0&per_page=50
2025-09-19 23:44:08,823 [INFO] novinhub - No more conversations to fetch from Goftino.
2025-09-19 23:44:08,823 [INFO] novinhub - Sync complete. New Conversations: 0, New Messages: 0, New Phones Assigned: 0.
2025-09-19 23:44:08,824 [INFO] novinhub - Database connection for Goftino sync closed.
2025-09-19 23:45:05,323 [INFO] novinhub - Goftino sync process has been scheduled in the background.
2025-09-19 23:45:05,343 [INFO] novinhub - Successfully connected to the MySQL database for Goftino sync.
2025-09-19 23:45:07,443 [ERROR] novinhub - Error fetching Goftino conversations: 400 Client Error: Bad Request for url: https://api.goftino.com/v1/conversations?page=0&per_page=50
2025-09-19 23:45:07,444 [INFO] novinhub - No more conversations to fetch from Goftino.
2025-09-19 23:45:07,444 [INFO] novinhub - Sync complete. New Conversations: 0, New Messages: 0, New Phones Assigned: 0.
2025-09-19 23:45:07,445 [INFO] novinhub - Database connection for Goftino sync closed.
2025-09-19 23:47:40,313 [INFO] novinhub - Goftino sync process has been scheduled in the background.
2025-09-19 23:47:40,332 [INFO] novinhub - Successfully connected to the MySQL database for Goftino sync.
2025-09-19 23:47:42,640 [INFO] novinhub - No more conversations to fetch from Goftino.
2025-09-19 23:47:42,640 [INFO] novinhub - Sync complete. New Conversations: 0, New Messages: 0, New Phones Assigned: 0.
2025-09-19 23:47:42,641 [INFO] novinhub - Database connection for Goftino sync closed.
2025-09-19 23:53:48,503 [INFO] novinhub - Goftino sync process has been scheduled in the background.
2025-09-19 23:53:48,525 [INFO] novinhub - Successfully connected to the MySQL database for Goftino sync.
2025-09-19 23:53:51,161 [INFO] novinhub - No more conversations to fetch from Goftino.
2025-09-19 23:53:51,162 [INFO] novinhub - Sync complete. New Conversations: 0, New Messages: 0, New Phones Assigned: 0.
2025-09-19 23:53:51,162 [INFO] novinhub - Database connection for Goftino sync closed.
2025-09-19 23:54:40,933 [INFO] novinhub - Goftino sync process has been scheduled in the background.
2025-09-19 23:54:40,952 [INFO] novinhub - Successfully connected to the MySQL database for Goftino sync.
2025-09-19 23:54:43,223 [INFO] novinhub - No more conversations to fetch from Goftino.
2025-09-19 23:54:43,224 [INFO] novinhub - Sync complete. New Conversations: 0, New Messages: 0, New Phones Assigned: 0.
2025-09-19 23:54:43,225 [INFO] novinhub - Database connection for Goftino sync closed.
2025-09-19 23:58:38,581 [INFO] novinhub - Goftino sync process has been scheduled in the background.
2025-09-19 23:58:38,602 [INFO] novinhub - Successfully connected to the MySQL database for Goftino sync.
2025-09-19 23:59:16,119 [ERROR] novinhub - An error occurred during Goftino sync: 1406 (22001): Data too long for column 'UserId' at row 1
Traceback (most recent call last):
  File "C:\Users\amira\AppData\Local\Programs\Python\Python313\Lib\site-packages\mysql\connector\connection_cext.py", line 772, in cmd_query
    self._cmysql.query(
    ~~~~~~~~~~~~~~~~~~^
        query,
        ^^^^^^
    ...<3 lines>...
        query_attrs=self.query_attrs,
        ^^^^^^^^^^^^^^^^^^^^^^^^^^^^^
    )
    ^
_mysql_connector.MySQLInterfaceError: Data too long for column 'UserId' at row 1

The above exception was the direct cause of the following exception:

Traceback (most recent call last):
  File "D:\MyProject\SalamatSaleDepartment\MainWebSite\WWW\python\ImportPhone_Novinhub.py", line 656, in sync_goftino_chats
    cursor.execute(
    ~~~~~~~~~~~~~~^
        "INSERT INTO goftino_conversations_header (ConversationId, UserId, Username, LastMessage, LastMessageTimestamp) VALUES (%s, %s, %s, %s, %s)",
        ^^^^^^^^^^^^^^^^^^^^^^^^^^^^^^^^^^^^^^^^^^^^^^^^^^^^^^^^^^^^^^^^^^^^^^^^^^^^^^^^^^^^^^^^^^^^^^^^^^^^^^^^^^^^^^^^^^^^^^^^^^^^^^^^^^^^^^^^^^^^^
        header_data
        ^^^^^^^^^^^
    )
    ^
  File "C:\Users\amira\AppData\Local\Programs\Python\Python313\Lib\site-packages\mysql\connector\cursor_cext.py", line 353, in execute
    self._connection.cmd_query(
    ~~~~~~~~~~~~~~~~~~~~~~~~~~^
        self._stmt_partition["mappable_stmt"],
        ^^^^^^^^^^^^^^^^^^^^^^^^^^^^^^^^^^^^^^
    ...<2 lines>...
        raw_as_string=self._raw_as_string,
        ^^^^^^^^^^^^^^^^^^^^^^^^^^^^^^^^^^
    )
    ^
  File "C:\Users\amira\AppData\Local\Programs\Python\Python313\Lib\site-packages\mysql\connector\opentelemetry\context_propagation.py", line 97, in wrapper
    return method(cnx, *args, **kwargs)
  File "C:\Users\amira\AppData\Local\Programs\Python\Python313\Lib\site-packages\mysql\connector\connection_cext.py", line 781, in cmd_query
    raise get_mysql_exception(
        err.errno, msg=err.msg, sqlstate=err.sqlstate
    ) from err
mysql.connector.errors.DataError: 1406 (22001): Data too long for column 'UserId' at row 1
2025-09-19 23:59:16,163 [INFO] novinhub - Database connection for Goftino sync closed.
2025-09-20 00:00:27,126 [INFO] novinhub - Goftino sync process has been scheduled in the background.
2025-09-20 00:00:27,153 [INFO] novinhub - Successfully connected to the MySQL database for Goftino sync.
2025-09-20 00:00:33,075 [ERROR] novinhub - An error occurred during Goftino sync: 1265 (01000): Data truncated for column 'LastMessageTimestamp' at row 1
Traceback (most recent call last):
  File "C:\Users\amira\AppData\Local\Programs\Python\Python313\Lib\site-packages\mysql\connector\connection_cext.py", line 772, in cmd_query
    self._cmysql.query(
    ~~~~~~~~~~~~~~~~~~^
        query,
        ^^^^^^
    ...<3 lines>...
        query_attrs=self.query_attrs,
        ^^^^^^^^^^^^^^^^^^^^^^^^^^^^^
    )
    ^
_mysql_connector.MySQLInterfaceError: Data truncated for column 'LastMessageTimestamp' at row 1

The above exception was the direct cause of the following exception:

Traceback (most recent call last):
  File "D:\MyProject\SalamatSaleDepartment\MainWebSite\WWW\python\ImportPhone_Novinhub.py", line 656, in sync_goftino_chats
    cursor.execute(
    ~~~~~~~~~~~~~~^
        "INSERT INTO goftino_conversations_header (ConversationId, UserId, Username, LastMessage, LastMessageTimestamp) VALUES (%s, %s, %s, %s, %s)",
        ^^^^^^^^^^^^^^^^^^^^^^^^^^^^^^^^^^^^^^^^^^^^^^^^^^^^^^^^^^^^^^^^^^^^^^^^^^^^^^^^^^^^^^^^^^^^^^^^^^^^^^^^^^^^^^^^^^^^^^^^^^^^^^^^^^^^^^^^^^^^^
        header_data
        ^^^^^^^^^^^
    )
    ^
  File "C:\Users\amira\AppData\Local\Programs\Python\Python313\Lib\site-packages\mysql\connector\cursor_cext.py", line 353, in execute
    self._connection.cmd_query(
    ~~~~~~~~~~~~~~~~~~~~~~~~~~^
        self._stmt_partition["mappable_stmt"],
        ^^^^^^^^^^^^^^^^^^^^^^^^^^^^^^^^^^^^^^
    ...<2 lines>...
        raw_as_string=self._raw_as_string,
        ^^^^^^^^^^^^^^^^^^^^^^^^^^^^^^^^^^
    )
    ^
  File "C:\Users\amira\AppData\Local\Programs\Python\Python313\Lib\site-packages\mysql\connector\opentelemetry\context_propagation.py", line 97, in wrapper
    return method(cnx, *args, **kwargs)
  File "C:\Users\amira\AppData\Local\Programs\Python\Python313\Lib\site-packages\mysql\connector\connection_cext.py", line 781, in cmd_query
    raise get_mysql_exception(
        err.errno, msg=err.msg, sqlstate=err.sqlstate
    ) from err
mysql.connector.errors.DatabaseError: 1265 (01000): Data truncated for column 'LastMessageTimestamp' at row 1
2025-09-20 00:00:33,078 [INFO] novinhub - Database connection for Goftino sync closed.
2025-09-20 01:01:19,273 [INFO] novinhub - Goftino sync process has been scheduled in the background.
2025-09-20 01:01:19,296 [INFO] novinhub - Successfully connected to the MySQL database for Goftino sync.
2025-09-20 01:01:21,977 [ERROR] novinhub - An error occurred during Goftino sync: 1265 (01000): Data truncated for column 'LastMessageTimestamp' at row 1
Traceback (most recent call last):
  File "C:\Users\amira\AppData\Local\Programs\Python\Python313\Lib\site-packages\mysql\connector\connection_cext.py", line 772, in cmd_query
    self._cmysql.query(
    ~~~~~~~~~~~~~~~~~~^
        query,
        ^^^^^^
    ...<3 lines>...
        query_attrs=self.query_attrs,
        ^^^^^^^^^^^^^^^^^^^^^^^^^^^^^
    )
    ^
_mysql_connector.MySQLInterfaceError: Data truncated for column 'LastMessageTimestamp' at row 1

The above exception was the direct cause of the following exception:

Traceback (most recent call last):
  File "D:\MyProject\SalamatSaleDepartment\MainWebSite\WWW\python\ImportPhone_Novinhub.py", line 656, in sync_goftino_chats
    cursor.execute(
    ~~~~~~~~~~~~~~^
        "INSERT INTO goftino_conversations_header (ConversationId, UserId, Username, LastMessage, LastMessageTimestamp) VALUES (%s, %s, %s, %s, %s)",
        ^^^^^^^^^^^^^^^^^^^^^^^^^^^^^^^^^^^^^^^^^^^^^^^^^^^^^^^^^^^^^^^^^^^^^^^^^^^^^^^^^^^^^^^^^^^^^^^^^^^^^^^^^^^^^^^^^^^^^^^^^^^^^^^^^^^^^^^^^^^^^
        header_data
        ^^^^^^^^^^^
    )
    ^
  File "C:\Users\amira\AppData\Local\Programs\Python\Python313\Lib\site-packages\mysql\connector\cursor_cext.py", line 353, in execute
    self._connection.cmd_query(
    ~~~~~~~~~~~~~~~~~~~~~~~~~~^
        self._stmt_partition["mappable_stmt"],
        ^^^^^^^^^^^^^^^^^^^^^^^^^^^^^^^^^^^^^^
    ...<2 lines>...
        raw_as_string=self._raw_as_string,
        ^^^^^^^^^^^^^^^^^^^^^^^^^^^^^^^^^^
    )
    ^
  File "C:\Users\amira\AppData\Local\Programs\Python\Python313\Lib\site-packages\mysql\connector\opentelemetry\context_propagation.py", line 97, in wrapper
    return method(cnx, *args, **kwargs)
  File "C:\Users\amira\AppData\Local\Programs\Python\Python313\Lib\site-packages\mysql\connector\connection_cext.py", line 781, in cmd_query
    raise get_mysql_exception(
        err.errno, msg=err.msg, sqlstate=err.sqlstate
    ) from err
mysql.connector.errors.DatabaseError: 1265 (01000): Data truncated for column 'LastMessageTimestamp' at row 1
2025-09-20 01:01:21,983 [INFO] novinhub - Database connection for Goftino sync closed.
2025-09-20 10:07:21,864 [INFO] novinhub - Background workflow task scheduled successfully.
2025-09-20 10:07:21,874 [INFO] novinhub - Background task started. Running the async workflow.
2025-09-20 10:07:21,875 [INFO] novinhub - Running robot before checking email...
2025-09-20 10:07:21,879 [INFO] novinhub - Starting Selenium robot...
2025-09-20 10:08:04,681 [INFO] novinhub - Opened start URL: https://app.novinhub.com/login?redirect=%2Fdashboard
2025-09-20 10:08:04,694 [INFO] novinhub - User is already logged in.
2025-09-20 10:08:04,694 [INFO] novinhub - Navigating to automation page...
2025-09-20 10:08:06,710 [INFO] novinhub - Navigating to export numbers tab...
2025-09-20 10:08:10,681 [INFO] novinhub - Clicking 'Export' button...
2025-09-20 10:08:12,066 [INFO] novinhub - Filling out the export modal form...
2025-09-20 10:08:13,136 [INFO] novinhub - Submitting the export request...
2025-09-20 10:08:14,396 [INFO] novinhub - Selenium robot has successfully requested the Excel file.
2025-09-20 10:08:16,625 [INFO] novinhub - Selenium robot finished.
2025-09-20 10:08:16,626 [INFO] novinhub - Authenticating Gmail API...
2025-09-20 10:08:17,117 [INFO] novinhub - Gmail service ready.
2025-09-20 10:08:17,118 [INFO] novinhub - Polling for report email for up to 180 seconds...
2025-09-20 10:08:17,995 [INFO] novinhub - No matching messages found for query.
2025-09-20 10:08:28,309 [INFO] novinhub - No matching messages found for query.
2025-09-20 10:08:38,645 [INFO] novinhub - No matching messages found for query.
2025-09-20 10:08:48,951 [INFO] novinhub - No matching messages found for query.
2025-09-20 10:08:59,257 [INFO] novinhub - No matching messages found for query.
2025-09-20 10:09:09,543 [INFO] novinhub - No matching messages found for query.
2025-09-20 10:09:19,858 [INFO] novinhub - No matching messages found for query.
2025-09-20 10:09:30,144 [INFO] novinhub - No matching messages found for query.
2025-09-20 10:09:40,436 [INFO] novinhub - No matching messages found for query.
2025-09-20 10:09:50,753 [INFO] novinhub - No matching messages found for query.
2025-09-20 10:10:01,058 [INFO] novinhub - No matching messages found for query.
2025-09-20 10:10:11,353 [INFO] novinhub - No matching messages found for query.
2025-09-20 10:10:22,003 [INFO] novinhub - Found message id=19965da1284d7681
2025-09-20 10:10:22,003 [INFO] novinhub - Looking for Excel attachment in message id=19965da1284d7681
2025-09-20 10:10:22,815 [INFO] novinhub - Attachment 'export.xlsx' downloaded (106117 bytes).
2025-09-20 10:10:22,815 [INFO] novinhub - Processing downloaded Excel...
2025-09-20 10:10:23,353 [INFO] novinhub - Connecting to MySQL at 127.0.0.1 database=salamatiancrm
2025-09-20 10:10:23,508 [INFO] novinhub - 2290 new records inserted.
2025-09-20 10:10:23,510 [INFO] novinhub - Processing result: {'success': True, 'message': '2290 new records were saved.'}
2025-09-20 10:10:23,511 [INFO] novinhub - Async workflow finished successfully in background.
2025-09-20 10:13:18,214 [INFO] novinhub - Background workflow task scheduled successfully.
2025-09-20 10:13:18,221 [INFO] novinhub - Background task started. Running the async workflow.
2025-09-20 10:13:18,222 [INFO] novinhub - Running robot before checking email...
2025-09-20 10:13:18,224 [INFO] novinhub - Starting Selenium robot...
2025-09-20 10:13:42,654 [INFO] novinhub - Opened start URL: https://app.novinhub.com/login?redirect=%2Fdashboard
2025-09-20 10:13:42,667 [INFO] novinhub - User is already logged in.
2025-09-20 10:13:42,667 [INFO] novinhub - Navigating to automation page...
2025-09-20 10:13:44,586 [INFO] novinhub - Navigating to export numbers tab...
2025-09-20 10:13:48,429 [INFO] novinhub - Clicking 'Export' button...
2025-09-20 10:13:49,371 [INFO] novinhub - Filling out the export modal form...
2025-09-20 10:13:50,377 [INFO] novinhub - Submitting the export request...
2025-09-20 10:13:55,436 [INFO] novinhub - Selenium robot has successfully requested the Excel file.
2025-09-20 10:13:57,608 [INFO] novinhub - Selenium robot finished.
2025-09-20 10:13:57,609 [INFO] novinhub - Authenticating Gmail API...
2025-09-20 10:13:57,621 [INFO] novinhub - Gmail service ready.
2025-09-20 10:13:57,622 [INFO] novinhub - Polling for report email for up to 180 seconds...
2025-09-20 10:13:59,108 [INFO] novinhub - Found message id=19965da1284d7681
2025-09-20 10:13:59,109 [INFO] novinhub - Looking for Excel attachment in message id=19965da1284d7681
2025-09-20 10:14:00,344 [INFO] novinhub - Attachment 'export.xlsx' downloaded (106117 bytes).
2025-09-20 10:14:00,344 [INFO] novinhub - Processing downloaded Excel...
2025-09-20 10:14:00,611 [INFO] novinhub - Connecting to MySQL at 127.0.0.1 database=salamatiancrm
2025-09-20 10:14:00,680 [INFO] novinhub - No new records to add.
2025-09-20 10:14:00,681 [INFO] novinhub - Processing result: {'success': True, 'message': 'No new records to add.'}
2025-09-20 10:14:00,682 [INFO] novinhub - Async workflow finished successfully in background.
2025-09-20 14:31:46,330 [INFO] novinhub - Background workflow task scheduled successfully.
2025-09-20 14:31:46,341 [INFO] novinhub - Background task started. Running the async workflow.
2025-09-20 14:31:46,343 [INFO] novinhub - Running robot before checking email...
2025-09-20 14:31:46,347 [INFO] novinhub - Starting Selenium robot...
2025-09-20 14:31:59,741 [INFO] novinhub - Opened start URL: https://app.novinhub.com/login?redirect=%2Fdashboard
2025-09-20 14:31:59,777 [INFO] novinhub - User is already logged in.
2025-09-20 14:31:59,778 [INFO] novinhub - Navigating to automation page...
2025-09-20 14:32:01,277 [INFO] novinhub - Navigating to export numbers tab...
2025-09-20 14:32:05,232 [INFO] novinhub - Clicking 'Export' button...
2025-09-20 14:32:06,658 [INFO] novinhub - Filling out the export modal form...
2025-09-20 14:32:07,408 [INFO] novinhub - Submitting the export request...
2025-09-20 14:32:12,504 [INFO] novinhub - Selenium robot has successfully requested the Excel file.
2025-09-20 14:32:15,807 [INFO] novinhub - Selenium robot finished.
2025-09-20 14:32:15,807 [INFO] novinhub - Authenticating Gmail API...
2025-09-20 14:32:16,500 [INFO] novinhub - Gmail service ready.
2025-09-20 14:32:16,501 [INFO] novinhub - Polling for report email for up to 180 seconds...
2025-09-20 14:32:17,545 [INFO] novinhub - No matching messages found for query.
2025-09-20 14:32:27,938 [INFO] novinhub - No matching messages found for query.
2025-09-20 14:32:38,344 [INFO] novinhub - No matching messages found for query.
2025-09-20 14:32:48,738 [INFO] novinhub - No matching messages found for query.
2025-09-20 14:32:59,117 [INFO] novinhub - No matching messages found for query.
2025-09-20 14:33:09,123 [ERROR] novinhub - Unexpected error while finding recent email.
Traceback (most recent call last):
  File "D:\MyProject\SalamatSaleDepartment\MainWebSite\WWW\python\ImportPhone_Novinhub.py", line 132, in find_recent_email
    resp = service.users().messages().list(userId='me', q=q, maxResults=max_results).execute()
  File "C:\Users\amira\AppData\Local\Programs\Python\Python313\Lib\site-packages\googleapiclient\_helpers.py", line 130, in positional_wrapper
    return wrapped(*args, **kwargs)
  File "C:\Users\amira\AppData\Local\Programs\Python\Python313\Lib\site-packages\googleapiclient\http.py", line 923, in execute
    resp, content = _retry_request(
                    ~~~~~~~~~~~~~~^
        http,
        ^^^^^
    ...<7 lines>...
        headers=self.headers,
        ^^^^^^^^^^^^^^^^^^^^^
    )
    ^
  File "C:\Users\amira\AppData\Local\Programs\Python\Python313\Lib\site-packages\googleapiclient\http.py", line 222, in _retry_request
    raise exception
  File "C:\Users\amira\AppData\Local\Programs\Python\Python313\Lib\site-packages\googleapiclient\http.py", line 191, in _retry_request
    resp, content = http.request(uri, method, *args, **kwargs)
                    ~~~~~~~~~~~~^^^^^^^^^^^^^^^^^^^^^^^^^^^^^^
  File "C:\Users\amira\AppData\Local\Programs\Python\Python313\Lib\site-packages\google_auth_httplib2.py", line 218, in request
    response, content = self.http.request(
                        ~~~~~~~~~~~~~~~~~^
        uri,
        ^^^^
    ...<5 lines>...
        **kwargs
        ^^^^^^^^
    )
    ^
  File "C:\Users\amira\AppData\Local\Programs\Python\Python313\Lib\site-packages\httplib2\__init__.py", line 1727, in request
    (response, content) = self._request(
                          ~~~~~~~~~~~~~^
        conn, authority, uri, request_uri, method, body, headers, redirections, cachekey,
        ^^^^^^^^^^^^^^^^^^^^^^^^^^^^^^^^^^^^^^^^^^^^^^^^^^^^^^^^^^^^^^^^^^^^^^^^^^^^^^^^^
    )
    ^
  File "C:\Users\amira\AppData\Local\Programs\Python\Python313\Lib\site-packages\httplib2\__init__.py", line 1447, in _request
    (response, content) = self._conn_request(conn, request_uri, method, body, headers)
                          ~~~~~~~~~~~~~~~~~~^^^^^^^^^^^^^^^^^^^^^^^^^^^^^^^^^^^^^^^^^^
  File "C:\Users\amira\AppData\Local\Programs\Python\Python313\Lib\site-packages\httplib2\__init__.py", line 1370, in _conn_request
    conn.request(method, request_uri, body, headers)
    ~~~~~~~~~~~~^^^^^^^^^^^^^^^^^^^^^^^^^^^^^^^^^^^^
  File "C:\Users\amira\AppData\Local\Programs\Python\Python313\Lib\http\client.py", line 1338, in request
    self._send_request(method, url, body, headers, encode_chunked)
    ~~~~~~~~~~~~~~~~~~^^^^^^^^^^^^^^^^^^^^^^^^^^^^^^^^^^^^^^^^^^^^
  File "C:\Users\amira\AppData\Local\Programs\Python\Python313\Lib\http\client.py", line 1384, in _send_request
    self.endheaders(body, encode_chunked=encode_chunked)
    ~~~~~~~~~~~~~~~^^^^^^^^^^^^^^^^^^^^^^^^^^^^^^^^^^^^^
  File "C:\Users\amira\AppData\Local\Programs\Python\Python313\Lib\http\client.py", line 1333, in endheaders
    self._send_output(message_body, encode_chunked=encode_chunked)
    ~~~~~~~~~~~~~~~~~^^^^^^^^^^^^^^^^^^^^^^^^^^^^^^^^^^^^^^^^^^^^^
  File "C:\Users\amira\AppData\Local\Programs\Python\Python313\Lib\http\client.py", line 1093, in _send_output
    self.send(msg)
    ~~~~~~~~~^^^^^
  File "C:\Users\amira\AppData\Local\Programs\Python\Python313\Lib\http\client.py", line 1057, in send
    self.sock.sendall(data)
    ~~~~~~~~~~~~~~~~~^^^^^^
  File "C:\Users\amira\AppData\Local\Programs\Python\Python313\Lib\ssl.py", line 1263, in sendall
    v = self.send(byte_view[count:])
  File "C:\Users\amira\AppData\Local\Programs\Python\Python313\Lib\ssl.py", line 1232, in send
    return self._sslobj.write(data)
           ~~~~~~~~~~~~~~~~~~^^^^^^
ConnectionResetError: [WinError 10054] An existing connection was forcibly closed by the remote host
2025-09-20 14:33:09,281 [ERROR] novinhub - Error in full workflow.
Traceback (most recent call last):
  File "D:\MyProject\SalamatSaleDepartment\MainWebSite\WWW\python\ImportPhone_Novinhub.py", line 512, in run_full_workflow
    msg = await asyncio.to_thread(find_recent_email, service)
          ^^^^^^^^^^^^^^^^^^^^^^^^^^^^^^^^^^^^^^^^^^^^^^^^^^^
  File "C:\Users\amira\AppData\Local\Programs\Python\Python313\Lib\asyncio\threads.py", line 25, in to_thread
    return await loop.run_in_executor(None, func_call)
           ^^^^^^^^^^^^^^^^^^^^^^^^^^^^^^^^^^^^^^^^^^^
  File "C:\Users\amira\AppData\Local\Programs\Python\Python313\Lib\concurrent\futures\thread.py", line 59, in run
    result = self.fn(*self.args, **self.kwargs)
  File "D:\MyProject\SalamatSaleDepartment\MainWebSite\WWW\python\ImportPhone_Novinhub.py", line 132, in find_recent_email
    resp = service.users().messages().list(userId='me', q=q, maxResults=max_results).execute()
  File "C:\Users\amira\AppData\Local\Programs\Python\Python313\Lib\site-packages\googleapiclient\_helpers.py", line 130, in positional_wrapper
    return wrapped(*args, **kwargs)
  File "C:\Users\amira\AppData\Local\Programs\Python\Python313\Lib\site-packages\googleapiclient\http.py", line 923, in execute
    resp, content = _retry_request(
                    ~~~~~~~~~~~~~~^
        http,
        ^^^^^
    ...<7 lines>...
        headers=self.headers,
        ^^^^^^^^^^^^^^^^^^^^^
    )
    ^
  File "C:\Users\amira\AppData\Local\Programs\Python\Python313\Lib\site-packages\googleapiclient\http.py", line 222, in _retry_request
    raise exception
  File "C:\Users\amira\AppData\Local\Programs\Python\Python313\Lib\site-packages\googleapiclient\http.py", line 191, in _retry_request
    resp, content = http.request(uri, method, *args, **kwargs)
                    ~~~~~~~~~~~~^^^^^^^^^^^^^^^^^^^^^^^^^^^^^^
  File "C:\Users\amira\AppData\Local\Programs\Python\Python313\Lib\site-packages\google_auth_httplib2.py", line 218, in request
    response, content = self.http.request(
                        ~~~~~~~~~~~~~~~~~^
        uri,
        ^^^^
    ...<5 lines>...
        **kwargs
        ^^^^^^^^
    )
    ^
  File "C:\Users\amira\AppData\Local\Programs\Python\Python313\Lib\site-packages\httplib2\__init__.py", line 1727, in request
    (response, content) = self._request(
                          ~~~~~~~~~~~~~^
        conn, authority, uri, request_uri, method, body, headers, redirections, cachekey,
        ^^^^^^^^^^^^^^^^^^^^^^^^^^^^^^^^^^^^^^^^^^^^^^^^^^^^^^^^^^^^^^^^^^^^^^^^^^^^^^^^^
    )
    ^
  File "C:\Users\amira\AppData\Local\Programs\Python\Python313\Lib\site-packages\httplib2\__init__.py", line 1447, in _request
    (response, content) = self._conn_request(conn, request_uri, method, body, headers)
                          ~~~~~~~~~~~~~~~~~~^^^^^^^^^^^^^^^^^^^^^^^^^^^^^^^^^^^^^^^^^^
  File "C:\Users\amira\AppData\Local\Programs\Python\Python313\Lib\site-packages\httplib2\__init__.py", line 1370, in _conn_request
    conn.request(method, request_uri, body, headers)
    ~~~~~~~~~~~~^^^^^^^^^^^^^^^^^^^^^^^^^^^^^^^^^^^^
  File "C:\Users\amira\AppData\Local\Programs\Python\Python313\Lib\http\client.py", line 1338, in request
    self._send_request(method, url, body, headers, encode_chunked)
    ~~~~~~~~~~~~~~~~~~^^^^^^^^^^^^^^^^^^^^^^^^^^^^^^^^^^^^^^^^^^^^
  File "C:\Users\amira\AppData\Local\Programs\Python\Python313\Lib\http\client.py", line 1384, in _send_request
    self.endheaders(body, encode_chunked=encode_chunked)
    ~~~~~~~~~~~~~~~^^^^^^^^^^^^^^^^^^^^^^^^^^^^^^^^^^^^^
  File "C:\Users\amira\AppData\Local\Programs\Python\Python313\Lib\http\client.py", line 1333, in endheaders
    self._send_output(message_body, encode_chunked=encode_chunked)
    ~~~~~~~~~~~~~~~~~^^^^^^^^^^^^^^^^^^^^^^^^^^^^^^^^^^^^^^^^^^^^^
  File "C:\Users\amira\AppData\Local\Programs\Python\Python313\Lib\http\client.py", line 1093, in _send_output
    self.send(msg)
    ~~~~~~~~~^^^^^
  File "C:\Users\amira\AppData\Local\Programs\Python\Python313\Lib\http\client.py", line 1057, in send
    self.sock.sendall(data)
    ~~~~~~~~~~~~~~~~~^^^^^^
  File "C:\Users\amira\AppData\Local\Programs\Python\Python313\Lib\ssl.py", line 1263, in sendall
    v = self.send(byte_view[count:])
  File "C:\Users\amira\AppData\Local\Programs\Python\Python313\Lib\ssl.py", line 1232, in send
    return self._sslobj.write(data)
           ~~~~~~~~~~~~~~~~~~^^^^^^
ConnectionResetError: [WinError 10054] An existing connection was forcibly closed by the remote host
2025-09-20 14:33:09,304 [INFO] novinhub - Async workflow finished successfully in background.
